[2025-09-22 13:52:57,912] INFO django.utils.autoreload:667 — Watching for file changes with StatReloader
[2025-09-22 13:53:45,353] INFO django.server:213 — "GET /admin/cart/cartitem/ HTTP/1.1" 200 15678
[2025-09-22 13:53:45,439] INFO django.server:213 — "GET /admin/jsi18n/ HTTP/1.1" 200 3342
[2025-09-22 13:53:45,715] WARNING django.request:253 — Not Found: /favicon.ico
[2025-09-22 13:53:45,718] WARNING django.server:213 — "GET /favicon.ico HTTP/1.1" 404 3299
[2025-09-22 13:53:56,947] INFO django.server:213 — "GET /cart/api/add/1/ HTTP/1.1" 200 7106
[2025-09-22 13:54:00,178] INFO django.server:213 — "GET /products/1/ HTTP/1.1" 200 6366
[2025-09-22 13:54:01,235] INFO django.server:213 — "GET /user/api/check-auth/ HTTP/1.1" 200 37
[2025-09-22 13:54:01,243] INFO django.server:213 — "GET /products/1/ HTTP/1.1" 200 791
[2025-09-22 13:54:01,263] INFO django.server:213 — "GET /media/catalog/487793279_I0LTg7r.png HTTP/1.1" 304 0
[2025-09-22 13:54:02,388] WARNING django.request:253 — Method Not Allowed: /cart/api/remove/1/
[2025-09-22 13:54:02,390] WARNING django.server:213 — "GET /cart/api/remove/1/ HTTP/1.1" 405 5245
[2025-09-22 13:54:03,376] WARNING django.request:253 — Method Not Allowed: /cart/api/remove/1/
[2025-09-22 13:54:03,377] WARNING django.server:213 — "GET /cart/api/remove/1/ HTTP/1.1" 405 5245
[2025-09-22 13:54:32,877] INFO django.server:213 — "GET /cart/ HTTP/1.1" 200 5258
[2025-09-22 13:54:34,899] INFO django.server:213 — "GET /cart/ HTTP/1.1" 200 5258
[2025-09-22 13:54:35,770] INFO django.server:213 — "GET /cart/ HTTP/1.1" 200 5258
[2025-09-22 13:54:42,950] INFO django.server:213 — "POST /cart/api/add/1/ HTTP/1.1" 200 7384
[2025-09-22 13:54:45,303] INFO django.server:213 — "GET /cart/ HTTP/1.1" 200 5535
<<<<<<< HEAD
[2025-09-22 14:28:18,913] INFO django.utils.autoreload:667 — Watching for file changes with StatReloader
[2025-09-22 14:28:24,503] INFO django.server:213 — "GET / HTTP/1.1" 200 7098
[2025-09-22 14:28:24,687] INFO django.server:213 — "GET /static/rest_framework/css/bootstrap.min.css HTTP/1.1" 304 0
[2025-09-22 14:28:24,688] INFO django.server:213 — "GET /static/rest_framework/css/bootstrap-tweaks.css HTTP/1.1" 304 0
[2025-09-22 14:28:24,695] INFO django.server:213 — "GET /static/rest_framework/js/bootstrap.min.js HTTP/1.1" 304 0
[2025-09-22 14:28:24,695] INFO django.server:213 — "GET /static/rest_framework/js/ajax-form.js HTTP/1.1" 304 0
[2025-09-22 14:28:24,698] INFO django.server:213 — "GET /static/rest_framework/css/prettify.css HTTP/1.1" 304 0
[2025-09-22 14:28:24,698] INFO django.server:213 — "GET /static/rest_framework/js/csrf.js HTTP/1.1" 304 0
[2025-09-22 14:28:24,699] INFO django.server:213 — "GET /static/rest_framework/css/default.css HTTP/1.1" 304 0
[2025-09-22 14:28:24,700] INFO django.server:213 — "GET /static/rest_framework/js/default.js HTTP/1.1" 304 0
[2025-09-22 14:28:24,701] INFO django.server:213 — "GET /static/rest_framework/js/load-ajax-form.js HTTP/1.1" 304 0
[2025-09-22 14:28:24,703] INFO django.server:213 — "GET /static/rest_framework/js/prettify-min.js HTTP/1.1" 304 0
[2025-09-22 14:28:24,705] INFO django.server:213 — "GET /static/rest_framework/js/jquery-3.7.1.min.js HTTP/1.1" 304 0
[2025-09-22 14:28:25,462] INFO django.server:213 — "GET /static/rest_framework/img/grid.png HTTP/1.1" 304 0
[2025-09-22 14:28:25,709] WARNING django.request:253 — Not Found: /favicon.ico
[2025-09-22 14:28:25,710] WARNING django.server:213 — "GET /favicon.ico HTTP/1.1" 404 3299
[2025-09-22 14:28:29,251] INFO django.server:213 — "GET / HTTP/1.1" 200 7076
[2025-09-22 14:28:29,583] INFO django.server:213 — "GET /static/rest_framework/img/grid.png HTTP/1.1" 200 1458
[2025-09-22 14:28:34,513] INFO django.server:213 — "GET /cart HTTP/1.1" 301 0
[2025-09-22 14:28:34,565] INFO django.server:213 — "GET /cart/ HTTP/1.1" 200 5240
[2025-09-22 14:28:56,966] WARNING django.request:253 — Not Found: /cart/add/1
[2025-09-22 14:28:56,966] WARNING django.server:213 — "GET /cart/add/1 HTTP/1.1" 404 4728
[2025-09-22 14:29:04,885] INFO django.server:213 — "GET /cart/api/add/1 HTTP/1.1" 301 0
[2025-09-22 14:29:04,933] INFO django.server:213 — "GET /cart/api/add/1/ HTTP/1.1" 200 7088
[2025-09-22 14:29:38,431] INFO django.server:213 — "POST /cart/api/add/1/ HTTP/1.1" 200 7364
[2025-09-22 14:29:51,221] INFO django.server:213 — "GET /cart/ HTTP/1.1" 200 5515
[2025-09-22 14:30:28,833] INFO django.server:213 — "GET /cart/api/add/2 HTTP/1.1" 301 0
[2025-09-22 14:30:28,869] INFO django.server:213 — "GET /cart/api/add/2/ HTTP/1.1" 200 7363
[2025-09-22 14:30:32,856] WARNING django.request:253 — Not Found: /cart/api/add/
[2025-09-22 14:30:32,857] WARNING django.server:213 — "GET /cart/api/add/ HTTP/1.1" 404 4737
[2025-09-22 14:30:35,197] INFO django.server:213 — "GET /cart/api/add/2 HTTP/1.1" 301 0
[2025-09-22 14:30:35,237] INFO django.server:213 — "GET /cart/api/add/2/ HTTP/1.1" 200 7363
[2025-09-22 14:30:51,309] INFO django.server:213 — "GET / HTTP/1.1" 200 7076
[2025-09-22 14:31:01,040] INFO django.server:213 — "GET / HTTP/1.1" 200 7098
[2025-09-22 14:31:02,540] WARNING django.request:253 — Not Found: /favicon.ico
[2025-09-22 14:31:02,543] WARNING django.server:213 — "GET /favicon.ico HTTP/1.1" 404 3299
[2025-09-22 14:36:09,868] INFO django.utils.autoreload:667 — Watching for file changes with StatReloader
[2025-09-22 14:39:20,638] INFO django.utils.autoreload:667 — Watching for file changes with StatReloader
[2025-09-22 14:39:23,832] WARNING django.request:253 — Not Found: /product/api
[2025-09-22 14:39:23,833] WARNING django.server:213 — "GET /product/api HTTP/1.1" 404 3299
[2025-09-22 14:39:24,138] INFO django.server:213 — "GET /products/api HTTP/1.1" 301 0
[2025-09-22 14:39:24,200] ERROR django.request:253 — Internal Server Error: /user/api/check-auth/
Traceback (most recent call last):
  File "/usr/local/lib/python3.12/site-packages/django/contrib/sessions/backends/base.py", line 244, in _get_session
    return self._session_cache
           ^^^^^^^^^^^^^^^^^^^
AttributeError: 'SessionStore' object has no attribute '_session_cache'

During handling of the above exception, another exception occurred:

Traceback (most recent call last):
  File "/usr/local/lib/python3.12/site-packages/django/db/backends/utils.py", line 105, in _execute
    return self.cursor.execute(sql, params)
           ^^^^^^^^^^^^^^^^^^^^^^^^^^^^^^^^
psycopg2.errors.UndefinedTable: relation "django_session" does not exist
LINE 1: ...ession_data", "django_session"."expire_date" FROM "django_se...
                                                             ^


The above exception was the direct cause of the following exception:

Traceback (most recent call last):
  File "/usr/local/lib/python3.12/site-packages/django/core/handlers/exception.py", line 55, in inner
    response = get_response(request)
               ^^^^^^^^^^^^^^^^^^^^^
  File "/usr/local/lib/python3.12/site-packages/django/core/handlers/base.py", line 197, in _get_response
    response = wrapped_callback(request, *callback_args, **callback_kwargs)
               ^^^^^^^^^^^^^^^^^^^^^^^^^^^^^^^^^^^^^^^^^^^^^^^^^^^^^^^^^^^^
  File "/usr/local/lib/python3.12/site-packages/django/views/decorators/csrf.py", line 65, in _view_wrapper
    return view_func(request, *args, **kwargs)
           ^^^^^^^^^^^^^^^^^^^^^^^^^^^^^^^^^^^
  File "/usr/local/lib/python3.12/site-packages/django/views/generic/base.py", line 105, in view
    return self.dispatch(request, *args, **kwargs)
           ^^^^^^^^^^^^^^^^^^^^^^^^^^^^^^^^^^^^^^^
  File "/usr/local/lib/python3.12/site-packages/rest_framework/views.py", line 515, in dispatch
    response = self.handle_exception(exc)
               ^^^^^^^^^^^^^^^^^^^^^^^^^^
  File "/usr/local/lib/python3.12/site-packages/rest_framework/views.py", line 475, in handle_exception
    self.raise_uncaught_exception(exc)
  File "/usr/local/lib/python3.12/site-packages/rest_framework/views.py", line 486, in raise_uncaught_exception
    raise exc
  File "/usr/local/lib/python3.12/site-packages/rest_framework/views.py", line 503, in dispatch
    self.initial(request, *args, **kwargs)
  File "/usr/local/lib/python3.12/site-packages/rest_framework/views.py", line 420, in initial
    self.perform_authentication(request)
  File "/usr/local/lib/python3.12/site-packages/rest_framework/views.py", line 330, in perform_authentication
    request.user
  File "/usr/local/lib/python3.12/site-packages/rest_framework/request.py", line 232, in user
    self._authenticate()
  File "/usr/local/lib/python3.12/site-packages/rest_framework/request.py", line 385, in _authenticate
    user_auth_tuple = authenticator.authenticate(self)
                      ^^^^^^^^^^^^^^^^^^^^^^^^^^^^^^^^
  File "/usr/local/lib/python3.12/site-packages/rest_framework/authentication.py", line 127, in authenticate
    if not user or not user.is_active:
           ^^^^
  File "/usr/local/lib/python3.12/site-packages/django/utils/functional.py", line 251, in inner
    self._setup()
  File "/usr/local/lib/python3.12/site-packages/django/utils/functional.py", line 404, in _setup
    self._wrapped = self._setupfunc()
                    ^^^^^^^^^^^^^^^^^
  File "/usr/local/lib/python3.12/site-packages/django/contrib/auth/middleware.py", line 40, in <lambda>
    request.user = SimpleLazyObject(lambda: get_user(request))
                                            ^^^^^^^^^^^^^^^^^
  File "/usr/local/lib/python3.12/site-packages/django/contrib/auth/middleware.py", line 20, in get_user
    request._cached_user = auth.get_user(request)
                           ^^^^^^^^^^^^^^^^^^^^^^
  File "/usr/local/lib/python3.12/site-packages/django/contrib/auth/__init__.py", line 304, in get_user
    user_id = _get_user_session_key(request)
              ^^^^^^^^^^^^^^^^^^^^^^^^^^^^^^
  File "/usr/local/lib/python3.12/site-packages/django/contrib/auth/__init__.py", line 95, in _get_user_session_key
    return get_user_model()._meta.pk.to_python(request.session[SESSION_KEY])
                                               ~~~~~~~~~~~~~~~^^^^^^^^^^^^^
  File "/usr/local/lib/python3.12/site-packages/django/contrib/sessions/backends/base.py", line 55, in __getitem__
    return self._session[key]
           ^^^^^^^^^^^^^
  File "/usr/local/lib/python3.12/site-packages/django/contrib/sessions/backends/base.py", line 249, in _get_session
    self._session_cache = self.load()
                          ^^^^^^^^^^^
  File "/usr/local/lib/python3.12/site-packages/django/contrib/sessions/backends/db.py", line 55, in load
    s = self._get_session_from_db()
        ^^^^^^^^^^^^^^^^^^^^^^^^^^^
  File "/usr/local/lib/python3.12/site-packages/django/contrib/sessions/backends/db.py", line 34, in _get_session_from_db
    return self.model.objects.get(
           ^^^^^^^^^^^^^^^^^^^^^^^
  File "/usr/local/lib/python3.12/site-packages/django/db/models/manager.py", line 87, in manager_method
    return getattr(self.get_queryset(), name)(*args, **kwargs)
           ^^^^^^^^^^^^^^^^^^^^^^^^^^^^^^^^^^^^^^^^^^^^^^^^^^^
  File "/usr/local/lib/python3.12/site-packages/django/db/models/query.py", line 629, in get
    num = len(clone)
          ^^^^^^^^^^
  File "/usr/local/lib/python3.12/site-packages/django/db/models/query.py", line 366, in __len__
    self._fetch_all()
  File "/usr/local/lib/python3.12/site-packages/django/db/models/query.py", line 1949, in _fetch_all
    self._result_cache = list(self._iterable_class(self))
                         ^^^^^^^^^^^^^^^^^^^^^^^^^^^^^^^^
  File "/usr/local/lib/python3.12/site-packages/django/db/models/query.py", line 91, in __iter__
    results = compiler.execute_sql(
              ^^^^^^^^^^^^^^^^^^^^^
  File "/usr/local/lib/python3.12/site-packages/django/db/models/sql/compiler.py", line 1623, in execute_sql
    cursor.execute(sql, params)
  File "/usr/local/lib/python3.12/site-packages/django/db/backends/utils.py", line 122, in execute
    return super().execute(sql, params)
           ^^^^^^^^^^^^^^^^^^^^^^^^^^^^
  File "/usr/local/lib/python3.12/site-packages/django/db/backends/utils.py", line 79, in execute
    return self._execute_with_wrappers(
           ^^^^^^^^^^^^^^^^^^^^^^^^^^^^
  File "/usr/local/lib/python3.12/site-packages/django/db/backends/utils.py", line 92, in _execute_with_wrappers
    return executor(sql, params, many, context)
           ^^^^^^^^^^^^^^^^^^^^^^^^^^^^^^^^^^^^
  File "/usr/local/lib/python3.12/site-packages/django/db/backends/utils.py", line 100, in _execute
    with self.db.wrap_database_errors:
         ^^^^^^^^^^^^^^^^^^^^^^^^^^^^
  File "/usr/local/lib/python3.12/site-packages/django/db/utils.py", line 91, in __exit__
    raise dj_exc_value.with_traceback(traceback) from exc_value
  File "/usr/local/lib/python3.12/site-packages/django/db/backends/utils.py", line 105, in _execute
    return self.cursor.execute(sql, params)
           ^^^^^^^^^^^^^^^^^^^^^^^^^^^^^^^^
django.db.utils.ProgrammingError: relation "django_session" does not exist
LINE 1: ...ession_data", "django_session"."expire_date" FROM "django_se...
                                                             ^

[2025-09-22 14:39:24,213] ERROR django.request:253 — Internal Server Error: /products/api/
[2025-09-22 14:39:24,215] ERROR django.server:213 — "GET /user/api/check-auth/ HTTP/1.1" 500 212403
[2025-09-22 14:39:24,215] ERROR django.server:213 — "GET /products/api/ HTTP/1.1" 500 223
[2025-09-22 14:39:24,899] WARNING django.request:253 — Not Found: /product/api
[2025-09-22 14:39:24,899] WARNING django.server:213 — "GET /product/api HTTP/1.1" 404 3299
[2025-09-22 14:39:28,555] INFO django.server:213 — "GET /products/api HTTP/1.1" 301 0
[2025-09-22 14:39:28,613] ERROR django.request:253 — Internal Server Error: /products/api/
Traceback (most recent call last):
  File "/usr/local/lib/python3.12/site-packages/django/contrib/sessions/backends/base.py", line 244, in _get_session
    return self._session_cache
           ^^^^^^^^^^^^^^^^^^^
AttributeError: 'SessionStore' object has no attribute '_session_cache'

During handling of the above exception, another exception occurred:

Traceback (most recent call last):
  File "/usr/local/lib/python3.12/site-packages/django/db/backends/utils.py", line 105, in _execute
    return self.cursor.execute(sql, params)
           ^^^^^^^^^^^^^^^^^^^^^^^^^^^^^^^^
psycopg2.errors.UndefinedTable: relation "django_session" does not exist
LINE 1: ...ession_data", "django_session"."expire_date" FROM "django_se...
                                                             ^


The above exception was the direct cause of the following exception:

Traceback (most recent call last):
  File "/usr/local/lib/python3.12/site-packages/django/core/handlers/exception.py", line 55, in inner
    response = get_response(request)
               ^^^^^^^^^^^^^^^^^^^^^
  File "/usr/local/lib/python3.12/site-packages/django/core/handlers/base.py", line 197, in _get_response
    response = wrapped_callback(request, *callback_args, **callback_kwargs)
               ^^^^^^^^^^^^^^^^^^^^^^^^^^^^^^^^^^^^^^^^^^^^^^^^^^^^^^^^^^^^
  File "/usr/local/lib/python3.12/site-packages/django/views/decorators/csrf.py", line 65, in _view_wrapper
    return view_func(request, *args, **kwargs)
           ^^^^^^^^^^^^^^^^^^^^^^^^^^^^^^^^^^^
  File "/usr/local/lib/python3.12/site-packages/django/views/generic/base.py", line 105, in view
    return self.dispatch(request, *args, **kwargs)
           ^^^^^^^^^^^^^^^^^^^^^^^^^^^^^^^^^^^^^^^
  File "/usr/local/lib/python3.12/site-packages/rest_framework/views.py", line 515, in dispatch
    response = self.handle_exception(exc)
               ^^^^^^^^^^^^^^^^^^^^^^^^^^
  File "/usr/local/lib/python3.12/site-packages/rest_framework/views.py", line 475, in handle_exception
    self.raise_uncaught_exception(exc)
  File "/usr/local/lib/python3.12/site-packages/rest_framework/views.py", line 486, in raise_uncaught_exception
    raise exc
  File "/usr/local/lib/python3.12/site-packages/rest_framework/views.py", line 503, in dispatch
    self.initial(request, *args, **kwargs)
  File "/usr/local/lib/python3.12/site-packages/rest_framework/views.py", line 420, in initial
    self.perform_authentication(request)
  File "/usr/local/lib/python3.12/site-packages/rest_framework/views.py", line 330, in perform_authentication
    request.user
  File "/usr/local/lib/python3.12/site-packages/rest_framework/request.py", line 232, in user
    self._authenticate()
  File "/usr/local/lib/python3.12/site-packages/rest_framework/request.py", line 385, in _authenticate
    user_auth_tuple = authenticator.authenticate(self)
                      ^^^^^^^^^^^^^^^^^^^^^^^^^^^^^^^^
  File "/usr/local/lib/python3.12/site-packages/rest_framework/authentication.py", line 127, in authenticate
    if not user or not user.is_active:
           ^^^^
  File "/usr/local/lib/python3.12/site-packages/django/utils/functional.py", line 251, in inner
    self._setup()
  File "/usr/local/lib/python3.12/site-packages/django/utils/functional.py", line 404, in _setup
    self._wrapped = self._setupfunc()
                    ^^^^^^^^^^^^^^^^^
  File "/usr/local/lib/python3.12/site-packages/django/contrib/auth/middleware.py", line 40, in <lambda>
    request.user = SimpleLazyObject(lambda: get_user(request))
                                            ^^^^^^^^^^^^^^^^^
  File "/usr/local/lib/python3.12/site-packages/django/contrib/auth/middleware.py", line 20, in get_user
    request._cached_user = auth.get_user(request)
                           ^^^^^^^^^^^^^^^^^^^^^^
  File "/usr/local/lib/python3.12/site-packages/django/contrib/auth/__init__.py", line 304, in get_user
    user_id = _get_user_session_key(request)
              ^^^^^^^^^^^^^^^^^^^^^^^^^^^^^^
  File "/usr/local/lib/python3.12/site-packages/django/contrib/auth/__init__.py", line 95, in _get_user_session_key
    return get_user_model()._meta.pk.to_python(request.session[SESSION_KEY])
                                               ~~~~~~~~~~~~~~~^^^^^^^^^^^^^
  File "/usr/local/lib/python3.12/site-packages/django/contrib/sessions/backends/base.py", line 55, in __getitem__
    return self._session[key]
           ^^^^^^^^^^^^^
  File "/usr/local/lib/python3.12/site-packages/django/contrib/sessions/backends/base.py", line 249, in _get_session
    self._session_cache = self.load()
                          ^^^^^^^^^^^
  File "/usr/local/lib/python3.12/site-packages/django/contrib/sessions/backends/db.py", line 55, in load
    s = self._get_session_from_db()
        ^^^^^^^^^^^^^^^^^^^^^^^^^^^
  File "/usr/local/lib/python3.12/site-packages/django/contrib/sessions/backends/db.py", line 34, in _get_session_from_db
    return self.model.objects.get(
           ^^^^^^^^^^^^^^^^^^^^^^^
  File "/usr/local/lib/python3.12/site-packages/django/db/models/manager.py", line 87, in manager_method
    return getattr(self.get_queryset(), name)(*args, **kwargs)
           ^^^^^^^^^^^^^^^^^^^^^^^^^^^^^^^^^^^^^^^^^^^^^^^^^^^
  File "/usr/local/lib/python3.12/site-packages/django/db/models/query.py", line 629, in get
    num = len(clone)
          ^^^^^^^^^^
  File "/usr/local/lib/python3.12/site-packages/django/db/models/query.py", line 366, in __len__
    self._fetch_all()
  File "/usr/local/lib/python3.12/site-packages/django/db/models/query.py", line 1949, in _fetch_all
    self._result_cache = list(self._iterable_class(self))
                         ^^^^^^^^^^^^^^^^^^^^^^^^^^^^^^^^
  File "/usr/local/lib/python3.12/site-packages/django/db/models/query.py", line 91, in __iter__
    results = compiler.execute_sql(
              ^^^^^^^^^^^^^^^^^^^^^
  File "/usr/local/lib/python3.12/site-packages/django/db/models/sql/compiler.py", line 1623, in execute_sql
    cursor.execute(sql, params)
  File "/usr/local/lib/python3.12/site-packages/django/db/backends/utils.py", line 122, in execute
    return super().execute(sql, params)
           ^^^^^^^^^^^^^^^^^^^^^^^^^^^^
  File "/usr/local/lib/python3.12/site-packages/django/db/backends/utils.py", line 79, in execute
    return self._execute_with_wrappers(
           ^^^^^^^^^^^^^^^^^^^^^^^^^^^^
  File "/usr/local/lib/python3.12/site-packages/django/db/backends/utils.py", line 92, in _execute_with_wrappers
    return executor(sql, params, many, context)
           ^^^^^^^^^^^^^^^^^^^^^^^^^^^^^^^^^^^^
  File "/usr/local/lib/python3.12/site-packages/django/db/backends/utils.py", line 100, in _execute
    with self.db.wrap_database_errors:
         ^^^^^^^^^^^^^^^^^^^^^^^^^^^^
  File "/usr/local/lib/python3.12/site-packages/django/db/utils.py", line 91, in __exit__
    raise dj_exc_value.with_traceback(traceback) from exc_value
  File "/usr/local/lib/python3.12/site-packages/django/db/backends/utils.py", line 105, in _execute
    return self.cursor.execute(sql, params)
           ^^^^^^^^^^^^^^^^^^^^^^^^^^^^^^^^
django.db.utils.ProgrammingError: relation "django_session" does not exist
LINE 1: ...ession_data", "django_session"."expire_date" FROM "django_se...
                                                             ^

[2025-09-22 14:39:28,618] ERROR django.server:213 — "GET /products/api/ HTTP/1.1" 500 212323
[2025-09-22 14:39:37,910] ERROR django.request:253 — Internal Server Error: /
Traceback (most recent call last):
  File "/usr/local/lib/python3.12/site-packages/django/contrib/sessions/backends/base.py", line 244, in _get_session
    return self._session_cache
           ^^^^^^^^^^^^^^^^^^^
AttributeError: 'SessionStore' object has no attribute '_session_cache'

During handling of the above exception, another exception occurred:

Traceback (most recent call last):
  File "/usr/local/lib/python3.12/site-packages/django/db/backends/utils.py", line 105, in _execute
    return self.cursor.execute(sql, params)
           ^^^^^^^^^^^^^^^^^^^^^^^^^^^^^^^^
psycopg2.errors.UndefinedTable: relation "django_session" does not exist
LINE 1: ...ession_data", "django_session"."expire_date" FROM "django_se...
                                                             ^


The above exception was the direct cause of the following exception:

Traceback (most recent call last):
  File "/usr/local/lib/python3.12/site-packages/django/core/handlers/exception.py", line 55, in inner
    response = get_response(request)
               ^^^^^^^^^^^^^^^^^^^^^
  File "/usr/local/lib/python3.12/site-packages/django/core/handlers/base.py", line 197, in _get_response
    response = wrapped_callback(request, *callback_args, **callback_kwargs)
               ^^^^^^^^^^^^^^^^^^^^^^^^^^^^^^^^^^^^^^^^^^^^^^^^^^^^^^^^^^^^
  File "/usr/local/lib/python3.12/site-packages/django/views/decorators/csrf.py", line 65, in _view_wrapper
    return view_func(request, *args, **kwargs)
           ^^^^^^^^^^^^^^^^^^^^^^^^^^^^^^^^^^^
  File "/usr/local/lib/python3.12/site-packages/django/views/generic/base.py", line 105, in view
    return self.dispatch(request, *args, **kwargs)
           ^^^^^^^^^^^^^^^^^^^^^^^^^^^^^^^^^^^^^^^
  File "/usr/local/lib/python3.12/site-packages/rest_framework/views.py", line 515, in dispatch
    response = self.handle_exception(exc)
               ^^^^^^^^^^^^^^^^^^^^^^^^^^
  File "/usr/local/lib/python3.12/site-packages/rest_framework/views.py", line 475, in handle_exception
    self.raise_uncaught_exception(exc)
  File "/usr/local/lib/python3.12/site-packages/rest_framework/views.py", line 486, in raise_uncaught_exception
    raise exc
  File "/usr/local/lib/python3.12/site-packages/rest_framework/views.py", line 503, in dispatch
    self.initial(request, *args, **kwargs)
  File "/usr/local/lib/python3.12/site-packages/rest_framework/views.py", line 420, in initial
    self.perform_authentication(request)
  File "/usr/local/lib/python3.12/site-packages/rest_framework/views.py", line 330, in perform_authentication
    request.user
  File "/usr/local/lib/python3.12/site-packages/rest_framework/request.py", line 232, in user
    self._authenticate()
  File "/usr/local/lib/python3.12/site-packages/rest_framework/request.py", line 385, in _authenticate
    user_auth_tuple = authenticator.authenticate(self)
                      ^^^^^^^^^^^^^^^^^^^^^^^^^^^^^^^^
  File "/usr/local/lib/python3.12/site-packages/rest_framework/authentication.py", line 127, in authenticate
    if not user or not user.is_active:
           ^^^^
  File "/usr/local/lib/python3.12/site-packages/django/utils/functional.py", line 251, in inner
    self._setup()
  File "/usr/local/lib/python3.12/site-packages/django/utils/functional.py", line 404, in _setup
    self._wrapped = self._setupfunc()
                    ^^^^^^^^^^^^^^^^^
  File "/usr/local/lib/python3.12/site-packages/django/contrib/auth/middleware.py", line 40, in <lambda>
    request.user = SimpleLazyObject(lambda: get_user(request))
                                            ^^^^^^^^^^^^^^^^^
  File "/usr/local/lib/python3.12/site-packages/django/contrib/auth/middleware.py", line 20, in get_user
    request._cached_user = auth.get_user(request)
                           ^^^^^^^^^^^^^^^^^^^^^^
  File "/usr/local/lib/python3.12/site-packages/django/contrib/auth/__init__.py", line 304, in get_user
    user_id = _get_user_session_key(request)
              ^^^^^^^^^^^^^^^^^^^^^^^^^^^^^^
  File "/usr/local/lib/python3.12/site-packages/django/contrib/auth/__init__.py", line 95, in _get_user_session_key
    return get_user_model()._meta.pk.to_python(request.session[SESSION_KEY])
                                               ~~~~~~~~~~~~~~~^^^^^^^^^^^^^
  File "/usr/local/lib/python3.12/site-packages/django/contrib/sessions/backends/base.py", line 55, in __getitem__
    return self._session[key]
           ^^^^^^^^^^^^^
  File "/usr/local/lib/python3.12/site-packages/django/contrib/sessions/backends/base.py", line 249, in _get_session
    self._session_cache = self.load()
                          ^^^^^^^^^^^
  File "/usr/local/lib/python3.12/site-packages/django/contrib/sessions/backends/db.py", line 55, in load
    s = self._get_session_from_db()
        ^^^^^^^^^^^^^^^^^^^^^^^^^^^
  File "/usr/local/lib/python3.12/site-packages/django/contrib/sessions/backends/db.py", line 34, in _get_session_from_db
    return self.model.objects.get(
           ^^^^^^^^^^^^^^^^^^^^^^^
  File "/usr/local/lib/python3.12/site-packages/django/db/models/manager.py", line 87, in manager_method
    return getattr(self.get_queryset(), name)(*args, **kwargs)
           ^^^^^^^^^^^^^^^^^^^^^^^^^^^^^^^^^^^^^^^^^^^^^^^^^^^
  File "/usr/local/lib/python3.12/site-packages/django/db/models/query.py", line 629, in get
    num = len(clone)
          ^^^^^^^^^^
  File "/usr/local/lib/python3.12/site-packages/django/db/models/query.py", line 366, in __len__
    self._fetch_all()
  File "/usr/local/lib/python3.12/site-packages/django/db/models/query.py", line 1949, in _fetch_all
    self._result_cache = list(self._iterable_class(self))
                         ^^^^^^^^^^^^^^^^^^^^^^^^^^^^^^^^
  File "/usr/local/lib/python3.12/site-packages/django/db/models/query.py", line 91, in __iter__
    results = compiler.execute_sql(
              ^^^^^^^^^^^^^^^^^^^^^
  File "/usr/local/lib/python3.12/site-packages/django/db/models/sql/compiler.py", line 1623, in execute_sql
    cursor.execute(sql, params)
  File "/usr/local/lib/python3.12/site-packages/django/db/backends/utils.py", line 122, in execute
    return super().execute(sql, params)
           ^^^^^^^^^^^^^^^^^^^^^^^^^^^^
  File "/usr/local/lib/python3.12/site-packages/django/db/backends/utils.py", line 79, in execute
    return self._execute_with_wrappers(
           ^^^^^^^^^^^^^^^^^^^^^^^^^^^^
  File "/usr/local/lib/python3.12/site-packages/django/db/backends/utils.py", line 92, in _execute_with_wrappers
    return executor(sql, params, many, context)
           ^^^^^^^^^^^^^^^^^^^^^^^^^^^^^^^^^^^^
  File "/usr/local/lib/python3.12/site-packages/django/db/backends/utils.py", line 100, in _execute
    with self.db.wrap_database_errors:
         ^^^^^^^^^^^^^^^^^^^^^^^^^^^^
  File "/usr/local/lib/python3.12/site-packages/django/db/utils.py", line 91, in __exit__
    raise dj_exc_value.with_traceback(traceback) from exc_value
  File "/usr/local/lib/python3.12/site-packages/django/db/backends/utils.py", line 105, in _execute
    return self.cursor.execute(sql, params)
           ^^^^^^^^^^^^^^^^^^^^^^^^^^^^^^^^
django.db.utils.ProgrammingError: relation "django_session" does not exist
LINE 1: ...ession_data", "django_session"."expire_date" FROM "django_se...
                                                             ^

[2025-09-22 14:39:37,915] ERROR django.server:213 — "GET / HTTP/1.1" 500 211960
[2025-09-22 14:39:39,442] ERROR django.request:253 — Internal Server Error: /
Traceback (most recent call last):
  File "/usr/local/lib/python3.12/site-packages/django/contrib/sessions/backends/base.py", line 244, in _get_session
    return self._session_cache
           ^^^^^^^^^^^^^^^^^^^
AttributeError: 'SessionStore' object has no attribute '_session_cache'

During handling of the above exception, another exception occurred:

Traceback (most recent call last):
  File "/usr/local/lib/python3.12/site-packages/django/db/backends/utils.py", line 105, in _execute
    return self.cursor.execute(sql, params)
           ^^^^^^^^^^^^^^^^^^^^^^^^^^^^^^^^
psycopg2.errors.UndefinedTable: relation "django_session" does not exist
LINE 1: ...ession_data", "django_session"."expire_date" FROM "django_se...
                                                             ^


The above exception was the direct cause of the following exception:

Traceback (most recent call last):
  File "/usr/local/lib/python3.12/site-packages/django/core/handlers/exception.py", line 55, in inner
    response = get_response(request)
               ^^^^^^^^^^^^^^^^^^^^^
  File "/usr/local/lib/python3.12/site-packages/django/core/handlers/base.py", line 197, in _get_response
    response = wrapped_callback(request, *callback_args, **callback_kwargs)
               ^^^^^^^^^^^^^^^^^^^^^^^^^^^^^^^^^^^^^^^^^^^^^^^^^^^^^^^^^^^^
  File "/usr/local/lib/python3.12/site-packages/django/views/decorators/csrf.py", line 65, in _view_wrapper
    return view_func(request, *args, **kwargs)
           ^^^^^^^^^^^^^^^^^^^^^^^^^^^^^^^^^^^
  File "/usr/local/lib/python3.12/site-packages/django/views/generic/base.py", line 105, in view
    return self.dispatch(request, *args, **kwargs)
           ^^^^^^^^^^^^^^^^^^^^^^^^^^^^^^^^^^^^^^^
  File "/usr/local/lib/python3.12/site-packages/rest_framework/views.py", line 515, in dispatch
    response = self.handle_exception(exc)
               ^^^^^^^^^^^^^^^^^^^^^^^^^^
  File "/usr/local/lib/python3.12/site-packages/rest_framework/views.py", line 475, in handle_exception
    self.raise_uncaught_exception(exc)
  File "/usr/local/lib/python3.12/site-packages/rest_framework/views.py", line 486, in raise_uncaught_exception
    raise exc
  File "/usr/local/lib/python3.12/site-packages/rest_framework/views.py", line 503, in dispatch
    self.initial(request, *args, **kwargs)
  File "/usr/local/lib/python3.12/site-packages/rest_framework/views.py", line 420, in initial
    self.perform_authentication(request)
  File "/usr/local/lib/python3.12/site-packages/rest_framework/views.py", line 330, in perform_authentication
    request.user
  File "/usr/local/lib/python3.12/site-packages/rest_framework/request.py", line 232, in user
    self._authenticate()
  File "/usr/local/lib/python3.12/site-packages/rest_framework/request.py", line 385, in _authenticate
    user_auth_tuple = authenticator.authenticate(self)
                      ^^^^^^^^^^^^^^^^^^^^^^^^^^^^^^^^
  File "/usr/local/lib/python3.12/site-packages/rest_framework/authentication.py", line 127, in authenticate
    if not user or not user.is_active:
           ^^^^
  File "/usr/local/lib/python3.12/site-packages/django/utils/functional.py", line 251, in inner
    self._setup()
  File "/usr/local/lib/python3.12/site-packages/django/utils/functional.py", line 404, in _setup
    self._wrapped = self._setupfunc()
                    ^^^^^^^^^^^^^^^^^
  File "/usr/local/lib/python3.12/site-packages/django/contrib/auth/middleware.py", line 40, in <lambda>
    request.user = SimpleLazyObject(lambda: get_user(request))
                                            ^^^^^^^^^^^^^^^^^
  File "/usr/local/lib/python3.12/site-packages/django/contrib/auth/middleware.py", line 20, in get_user
    request._cached_user = auth.get_user(request)
                           ^^^^^^^^^^^^^^^^^^^^^^
  File "/usr/local/lib/python3.12/site-packages/django/contrib/auth/__init__.py", line 304, in get_user
    user_id = _get_user_session_key(request)
              ^^^^^^^^^^^^^^^^^^^^^^^^^^^^^^
  File "/usr/local/lib/python3.12/site-packages/django/contrib/auth/__init__.py", line 95, in _get_user_session_key
    return get_user_model()._meta.pk.to_python(request.session[SESSION_KEY])
                                               ~~~~~~~~~~~~~~~^^^^^^^^^^^^^
  File "/usr/local/lib/python3.12/site-packages/django/contrib/sessions/backends/base.py", line 55, in __getitem__
    return self._session[key]
           ^^^^^^^^^^^^^
  File "/usr/local/lib/python3.12/site-packages/django/contrib/sessions/backends/base.py", line 249, in _get_session
    self._session_cache = self.load()
                          ^^^^^^^^^^^
  File "/usr/local/lib/python3.12/site-packages/django/contrib/sessions/backends/db.py", line 55, in load
    s = self._get_session_from_db()
        ^^^^^^^^^^^^^^^^^^^^^^^^^^^
  File "/usr/local/lib/python3.12/site-packages/django/contrib/sessions/backends/db.py", line 34, in _get_session_from_db
    return self.model.objects.get(
           ^^^^^^^^^^^^^^^^^^^^^^^
  File "/usr/local/lib/python3.12/site-packages/django/db/models/manager.py", line 87, in manager_method
    return getattr(self.get_queryset(), name)(*args, **kwargs)
           ^^^^^^^^^^^^^^^^^^^^^^^^^^^^^^^^^^^^^^^^^^^^^^^^^^^
  File "/usr/local/lib/python3.12/site-packages/django/db/models/query.py", line 629, in get
    num = len(clone)
          ^^^^^^^^^^
  File "/usr/local/lib/python3.12/site-packages/django/db/models/query.py", line 366, in __len__
    self._fetch_all()
  File "/usr/local/lib/python3.12/site-packages/django/db/models/query.py", line 1949, in _fetch_all
    self._result_cache = list(self._iterable_class(self))
                         ^^^^^^^^^^^^^^^^^^^^^^^^^^^^^^^^
  File "/usr/local/lib/python3.12/site-packages/django/db/models/query.py", line 91, in __iter__
    results = compiler.execute_sql(
              ^^^^^^^^^^^^^^^^^^^^^
  File "/usr/local/lib/python3.12/site-packages/django/db/models/sql/compiler.py", line 1623, in execute_sql
    cursor.execute(sql, params)
  File "/usr/local/lib/python3.12/site-packages/django/db/backends/utils.py", line 122, in execute
    return super().execute(sql, params)
           ^^^^^^^^^^^^^^^^^^^^^^^^^^^^
  File "/usr/local/lib/python3.12/site-packages/django/db/backends/utils.py", line 79, in execute
    return self._execute_with_wrappers(
           ^^^^^^^^^^^^^^^^^^^^^^^^^^^^
  File "/usr/local/lib/python3.12/site-packages/django/db/backends/utils.py", line 92, in _execute_with_wrappers
    return executor(sql, params, many, context)
           ^^^^^^^^^^^^^^^^^^^^^^^^^^^^^^^^^^^^
  File "/usr/local/lib/python3.12/site-packages/django/db/backends/utils.py", line 100, in _execute
    with self.db.wrap_database_errors:
         ^^^^^^^^^^^^^^^^^^^^^^^^^^^^
  File "/usr/local/lib/python3.12/site-packages/django/db/utils.py", line 91, in __exit__
    raise dj_exc_value.with_traceback(traceback) from exc_value
  File "/usr/local/lib/python3.12/site-packages/django/db/backends/utils.py", line 105, in _execute
    return self.cursor.execute(sql, params)
           ^^^^^^^^^^^^^^^^^^^^^^^^^^^^^^^^
django.db.utils.ProgrammingError: relation "django_session" does not exist
LINE 1: ...ession_data", "django_session"."expire_date" FROM "django_se...
                                                             ^

[2025-09-22 14:39:39,447] ERROR django.server:213 — "GET / HTTP/1.1" 500 211960
[2025-09-22 14:39:42,765] ERROR django.request:253 — Internal Server Error: /
Traceback (most recent call last):
  File "/usr/local/lib/python3.12/site-packages/django/contrib/sessions/backends/base.py", line 244, in _get_session
    return self._session_cache
           ^^^^^^^^^^^^^^^^^^^
AttributeError: 'SessionStore' object has no attribute '_session_cache'

During handling of the above exception, another exception occurred:

Traceback (most recent call last):
  File "/usr/local/lib/python3.12/site-packages/django/db/backends/utils.py", line 105, in _execute
    return self.cursor.execute(sql, params)
           ^^^^^^^^^^^^^^^^^^^^^^^^^^^^^^^^
psycopg2.errors.UndefinedTable: relation "django_session" does not exist
LINE 1: ...ession_data", "django_session"."expire_date" FROM "django_se...
                                                             ^


The above exception was the direct cause of the following exception:

Traceback (most recent call last):
  File "/usr/local/lib/python3.12/site-packages/django/core/handlers/exception.py", line 55, in inner
    response = get_response(request)
               ^^^^^^^^^^^^^^^^^^^^^
  File "/usr/local/lib/python3.12/site-packages/django/core/handlers/base.py", line 197, in _get_response
    response = wrapped_callback(request, *callback_args, **callback_kwargs)
               ^^^^^^^^^^^^^^^^^^^^^^^^^^^^^^^^^^^^^^^^^^^^^^^^^^^^^^^^^^^^
  File "/usr/local/lib/python3.12/site-packages/django/views/decorators/csrf.py", line 65, in _view_wrapper
    return view_func(request, *args, **kwargs)
           ^^^^^^^^^^^^^^^^^^^^^^^^^^^^^^^^^^^
  File "/usr/local/lib/python3.12/site-packages/django/views/generic/base.py", line 105, in view
    return self.dispatch(request, *args, **kwargs)
           ^^^^^^^^^^^^^^^^^^^^^^^^^^^^^^^^^^^^^^^
  File "/usr/local/lib/python3.12/site-packages/rest_framework/views.py", line 515, in dispatch
    response = self.handle_exception(exc)
               ^^^^^^^^^^^^^^^^^^^^^^^^^^
  File "/usr/local/lib/python3.12/site-packages/rest_framework/views.py", line 475, in handle_exception
    self.raise_uncaught_exception(exc)
  File "/usr/local/lib/python3.12/site-packages/rest_framework/views.py", line 486, in raise_uncaught_exception
    raise exc
  File "/usr/local/lib/python3.12/site-packages/rest_framework/views.py", line 503, in dispatch
    self.initial(request, *args, **kwargs)
  File "/usr/local/lib/python3.12/site-packages/rest_framework/views.py", line 420, in initial
    self.perform_authentication(request)
  File "/usr/local/lib/python3.12/site-packages/rest_framework/views.py", line 330, in perform_authentication
    request.user
  File "/usr/local/lib/python3.12/site-packages/rest_framework/request.py", line 232, in user
    self._authenticate()
  File "/usr/local/lib/python3.12/site-packages/rest_framework/request.py", line 385, in _authenticate
    user_auth_tuple = authenticator.authenticate(self)
                      ^^^^^^^^^^^^^^^^^^^^^^^^^^^^^^^^
  File "/usr/local/lib/python3.12/site-packages/rest_framework/authentication.py", line 127, in authenticate
    if not user or not user.is_active:
           ^^^^
  File "/usr/local/lib/python3.12/site-packages/django/utils/functional.py", line 251, in inner
    self._setup()
  File "/usr/local/lib/python3.12/site-packages/django/utils/functional.py", line 404, in _setup
    self._wrapped = self._setupfunc()
                    ^^^^^^^^^^^^^^^^^
  File "/usr/local/lib/python3.12/site-packages/django/contrib/auth/middleware.py", line 40, in <lambda>
    request.user = SimpleLazyObject(lambda: get_user(request))
                                            ^^^^^^^^^^^^^^^^^
  File "/usr/local/lib/python3.12/site-packages/django/contrib/auth/middleware.py", line 20, in get_user
    request._cached_user = auth.get_user(request)
                           ^^^^^^^^^^^^^^^^^^^^^^
  File "/usr/local/lib/python3.12/site-packages/django/contrib/auth/__init__.py", line 304, in get_user
    user_id = _get_user_session_key(request)
              ^^^^^^^^^^^^^^^^^^^^^^^^^^^^^^
  File "/usr/local/lib/python3.12/site-packages/django/contrib/auth/__init__.py", line 95, in _get_user_session_key
    return get_user_model()._meta.pk.to_python(request.session[SESSION_KEY])
                                               ~~~~~~~~~~~~~~~^^^^^^^^^^^^^
  File "/usr/local/lib/python3.12/site-packages/django/contrib/sessions/backends/base.py", line 55, in __getitem__
    return self._session[key]
           ^^^^^^^^^^^^^
  File "/usr/local/lib/python3.12/site-packages/django/contrib/sessions/backends/base.py", line 249, in _get_session
    self._session_cache = self.load()
                          ^^^^^^^^^^^
  File "/usr/local/lib/python3.12/site-packages/django/contrib/sessions/backends/db.py", line 55, in load
    s = self._get_session_from_db()
        ^^^^^^^^^^^^^^^^^^^^^^^^^^^
  File "/usr/local/lib/python3.12/site-packages/django/contrib/sessions/backends/db.py", line 34, in _get_session_from_db
    return self.model.objects.get(
           ^^^^^^^^^^^^^^^^^^^^^^^
  File "/usr/local/lib/python3.12/site-packages/django/db/models/manager.py", line 87, in manager_method
    return getattr(self.get_queryset(), name)(*args, **kwargs)
           ^^^^^^^^^^^^^^^^^^^^^^^^^^^^^^^^^^^^^^^^^^^^^^^^^^^
  File "/usr/local/lib/python3.12/site-packages/django/db/models/query.py", line 629, in get
    num = len(clone)
          ^^^^^^^^^^
  File "/usr/local/lib/python3.12/site-packages/django/db/models/query.py", line 366, in __len__
    self._fetch_all()
  File "/usr/local/lib/python3.12/site-packages/django/db/models/query.py", line 1949, in _fetch_all
    self._result_cache = list(self._iterable_class(self))
                         ^^^^^^^^^^^^^^^^^^^^^^^^^^^^^^^^
  File "/usr/local/lib/python3.12/site-packages/django/db/models/query.py", line 91, in __iter__
    results = compiler.execute_sql(
              ^^^^^^^^^^^^^^^^^^^^^
  File "/usr/local/lib/python3.12/site-packages/django/db/models/sql/compiler.py", line 1623, in execute_sql
    cursor.execute(sql, params)
  File "/usr/local/lib/python3.12/site-packages/django/db/backends/utils.py", line 122, in execute
    return super().execute(sql, params)
           ^^^^^^^^^^^^^^^^^^^^^^^^^^^^
  File "/usr/local/lib/python3.12/site-packages/django/db/backends/utils.py", line 79, in execute
    return self._execute_with_wrappers(
           ^^^^^^^^^^^^^^^^^^^^^^^^^^^^
  File "/usr/local/lib/python3.12/site-packages/django/db/backends/utils.py", line 92, in _execute_with_wrappers
    return executor(sql, params, many, context)
           ^^^^^^^^^^^^^^^^^^^^^^^^^^^^^^^^^^^^
  File "/usr/local/lib/python3.12/site-packages/django/db/backends/utils.py", line 100, in _execute
    with self.db.wrap_database_errors:
         ^^^^^^^^^^^^^^^^^^^^^^^^^^^^
  File "/usr/local/lib/python3.12/site-packages/django/db/utils.py", line 91, in __exit__
    raise dj_exc_value.with_traceback(traceback) from exc_value
  File "/usr/local/lib/python3.12/site-packages/django/db/backends/utils.py", line 105, in _execute
    return self.cursor.execute(sql, params)
           ^^^^^^^^^^^^^^^^^^^^^^^^^^^^^^^^
django.db.utils.ProgrammingError: relation "django_session" does not exist
LINE 1: ...ession_data", "django_session"."expire_date" FROM "django_se...
                                                             ^

[2025-09-22 14:39:42,770] ERROR django.server:213 — "GET / HTTP/1.1" 500 211960
[2025-09-22 14:40:57,416] INFO django.utils.autoreload:265 — /app/backend/settings.py changed, reloading.
[2025-09-22 14:40:58,654] INFO django.utils.autoreload:667 — Watching for file changes with StatReloader
[2025-09-22 14:41:33,310] ERROR django.request:253 — Internal Server Error: /
Traceback (most recent call last):
  File "/usr/local/lib/python3.12/site-packages/django/contrib/sessions/backends/base.py", line 244, in _get_session
    return self._session_cache
           ^^^^^^^^^^^^^^^^^^^
AttributeError: 'SessionStore' object has no attribute '_session_cache'

During handling of the above exception, another exception occurred:

Traceback (most recent call last):
  File "/usr/local/lib/python3.12/site-packages/django/db/backends/utils.py", line 105, in _execute
    return self.cursor.execute(sql, params)
           ^^^^^^^^^^^^^^^^^^^^^^^^^^^^^^^^
psycopg2.errors.UndefinedTable: relation "django_session" does not exist
LINE 1: ...ession_data", "django_session"."expire_date" FROM "django_se...
                                                             ^


The above exception was the direct cause of the following exception:

Traceback (most recent call last):
  File "/usr/local/lib/python3.12/site-packages/django/core/handlers/exception.py", line 55, in inner
    response = get_response(request)
               ^^^^^^^^^^^^^^^^^^^^^
  File "/usr/local/lib/python3.12/site-packages/django/core/handlers/base.py", line 197, in _get_response
    response = wrapped_callback(request, *callback_args, **callback_kwargs)
               ^^^^^^^^^^^^^^^^^^^^^^^^^^^^^^^^^^^^^^^^^^^^^^^^^^^^^^^^^^^^
  File "/usr/local/lib/python3.12/site-packages/django/views/decorators/csrf.py", line 65, in _view_wrapper
    return view_func(request, *args, **kwargs)
           ^^^^^^^^^^^^^^^^^^^^^^^^^^^^^^^^^^^
  File "/usr/local/lib/python3.12/site-packages/django/views/generic/base.py", line 105, in view
    return self.dispatch(request, *args, **kwargs)
           ^^^^^^^^^^^^^^^^^^^^^^^^^^^^^^^^^^^^^^^
  File "/usr/local/lib/python3.12/site-packages/rest_framework/views.py", line 515, in dispatch
    response = self.handle_exception(exc)
               ^^^^^^^^^^^^^^^^^^^^^^^^^^
  File "/usr/local/lib/python3.12/site-packages/rest_framework/views.py", line 475, in handle_exception
    self.raise_uncaught_exception(exc)
  File "/usr/local/lib/python3.12/site-packages/rest_framework/views.py", line 486, in raise_uncaught_exception
    raise exc
  File "/usr/local/lib/python3.12/site-packages/rest_framework/views.py", line 503, in dispatch
    self.initial(request, *args, **kwargs)
  File "/usr/local/lib/python3.12/site-packages/rest_framework/views.py", line 420, in initial
    self.perform_authentication(request)
  File "/usr/local/lib/python3.12/site-packages/rest_framework/views.py", line 330, in perform_authentication
    request.user
  File "/usr/local/lib/python3.12/site-packages/rest_framework/request.py", line 232, in user
    self._authenticate()
  File "/usr/local/lib/python3.12/site-packages/rest_framework/request.py", line 385, in _authenticate
    user_auth_tuple = authenticator.authenticate(self)
                      ^^^^^^^^^^^^^^^^^^^^^^^^^^^^^^^^
  File "/usr/local/lib/python3.12/site-packages/rest_framework/authentication.py", line 127, in authenticate
    if not user or not user.is_active:
           ^^^^
  File "/usr/local/lib/python3.12/site-packages/django/utils/functional.py", line 251, in inner
    self._setup()
  File "/usr/local/lib/python3.12/site-packages/django/utils/functional.py", line 404, in _setup
    self._wrapped = self._setupfunc()
                    ^^^^^^^^^^^^^^^^^
  File "/usr/local/lib/python3.12/site-packages/django/contrib/auth/middleware.py", line 40, in <lambda>
    request.user = SimpleLazyObject(lambda: get_user(request))
                                            ^^^^^^^^^^^^^^^^^
  File "/usr/local/lib/python3.12/site-packages/django/contrib/auth/middleware.py", line 20, in get_user
    request._cached_user = auth.get_user(request)
                           ^^^^^^^^^^^^^^^^^^^^^^
  File "/usr/local/lib/python3.12/site-packages/django/contrib/auth/__init__.py", line 304, in get_user
    user_id = _get_user_session_key(request)
              ^^^^^^^^^^^^^^^^^^^^^^^^^^^^^^
  File "/usr/local/lib/python3.12/site-packages/django/contrib/auth/__init__.py", line 95, in _get_user_session_key
    return get_user_model()._meta.pk.to_python(request.session[SESSION_KEY])
                                               ~~~~~~~~~~~~~~~^^^^^^^^^^^^^
  File "/usr/local/lib/python3.12/site-packages/django/contrib/sessions/backends/base.py", line 55, in __getitem__
    return self._session[key]
           ^^^^^^^^^^^^^
  File "/usr/local/lib/python3.12/site-packages/django/contrib/sessions/backends/base.py", line 249, in _get_session
    self._session_cache = self.load()
                          ^^^^^^^^^^^
  File "/usr/local/lib/python3.12/site-packages/django/contrib/sessions/backends/db.py", line 55, in load
    s = self._get_session_from_db()
        ^^^^^^^^^^^^^^^^^^^^^^^^^^^
  File "/usr/local/lib/python3.12/site-packages/django/contrib/sessions/backends/db.py", line 34, in _get_session_from_db
    return self.model.objects.get(
           ^^^^^^^^^^^^^^^^^^^^^^^
  File "/usr/local/lib/python3.12/site-packages/django/db/models/manager.py", line 87, in manager_method
    return getattr(self.get_queryset(), name)(*args, **kwargs)
           ^^^^^^^^^^^^^^^^^^^^^^^^^^^^^^^^^^^^^^^^^^^^^^^^^^^
  File "/usr/local/lib/python3.12/site-packages/django/db/models/query.py", line 629, in get
    num = len(clone)
          ^^^^^^^^^^
  File "/usr/local/lib/python3.12/site-packages/django/db/models/query.py", line 366, in __len__
    self._fetch_all()
  File "/usr/local/lib/python3.12/site-packages/django/db/models/query.py", line 1949, in _fetch_all
    self._result_cache = list(self._iterable_class(self))
                         ^^^^^^^^^^^^^^^^^^^^^^^^^^^^^^^^
  File "/usr/local/lib/python3.12/site-packages/django/db/models/query.py", line 91, in __iter__
    results = compiler.execute_sql(
              ^^^^^^^^^^^^^^^^^^^^^
  File "/usr/local/lib/python3.12/site-packages/django/db/models/sql/compiler.py", line 1623, in execute_sql
    cursor.execute(sql, params)
  File "/usr/local/lib/python3.12/site-packages/django/db/backends/utils.py", line 122, in execute
    return super().execute(sql, params)
           ^^^^^^^^^^^^^^^^^^^^^^^^^^^^
  File "/usr/local/lib/python3.12/site-packages/django/db/backends/utils.py", line 79, in execute
    return self._execute_with_wrappers(
           ^^^^^^^^^^^^^^^^^^^^^^^^^^^^
  File "/usr/local/lib/python3.12/site-packages/django/db/backends/utils.py", line 92, in _execute_with_wrappers
    return executor(sql, params, many, context)
           ^^^^^^^^^^^^^^^^^^^^^^^^^^^^^^^^^^^^
  File "/usr/local/lib/python3.12/site-packages/django/db/backends/utils.py", line 100, in _execute
    with self.db.wrap_database_errors:
         ^^^^^^^^^^^^^^^^^^^^^^^^^^^^
  File "/usr/local/lib/python3.12/site-packages/django/db/utils.py", line 91, in __exit__
    raise dj_exc_value.with_traceback(traceback) from exc_value
  File "/usr/local/lib/python3.12/site-packages/django/db/backends/utils.py", line 105, in _execute
    return self.cursor.execute(sql, params)
           ^^^^^^^^^^^^^^^^^^^^^^^^^^^^^^^^
django.db.utils.ProgrammingError: relation "django_session" does not exist
LINE 1: ...ession_data", "django_session"."expire_date" FROM "django_se...
                                                             ^

[2025-09-22 14:41:33,316] ERROR django.server:213 — "GET / HTTP/1.1" 500 211995
[2025-09-22 14:41:34,210] ERROR django.request:253 — Internal Server Error: /
Traceback (most recent call last):
  File "/usr/local/lib/python3.12/site-packages/django/contrib/sessions/backends/base.py", line 244, in _get_session
    return self._session_cache
           ^^^^^^^^^^^^^^^^^^^
AttributeError: 'SessionStore' object has no attribute '_session_cache'

During handling of the above exception, another exception occurred:

Traceback (most recent call last):
  File "/usr/local/lib/python3.12/site-packages/django/db/backends/utils.py", line 105, in _execute
    return self.cursor.execute(sql, params)
           ^^^^^^^^^^^^^^^^^^^^^^^^^^^^^^^^
psycopg2.errors.UndefinedTable: relation "django_session" does not exist
LINE 1: ...ession_data", "django_session"."expire_date" FROM "django_se...
                                                             ^


The above exception was the direct cause of the following exception:

Traceback (most recent call last):
  File "/usr/local/lib/python3.12/site-packages/django/core/handlers/exception.py", line 55, in inner
    response = get_response(request)
               ^^^^^^^^^^^^^^^^^^^^^
  File "/usr/local/lib/python3.12/site-packages/django/core/handlers/base.py", line 197, in _get_response
    response = wrapped_callback(request, *callback_args, **callback_kwargs)
               ^^^^^^^^^^^^^^^^^^^^^^^^^^^^^^^^^^^^^^^^^^^^^^^^^^^^^^^^^^^^
  File "/usr/local/lib/python3.12/site-packages/django/views/decorators/csrf.py", line 65, in _view_wrapper
    return view_func(request, *args, **kwargs)
           ^^^^^^^^^^^^^^^^^^^^^^^^^^^^^^^^^^^
  File "/usr/local/lib/python3.12/site-packages/django/views/generic/base.py", line 105, in view
    return self.dispatch(request, *args, **kwargs)
           ^^^^^^^^^^^^^^^^^^^^^^^^^^^^^^^^^^^^^^^
  File "/usr/local/lib/python3.12/site-packages/rest_framework/views.py", line 515, in dispatch
    response = self.handle_exception(exc)
               ^^^^^^^^^^^^^^^^^^^^^^^^^^
  File "/usr/local/lib/python3.12/site-packages/rest_framework/views.py", line 475, in handle_exception
    self.raise_uncaught_exception(exc)
  File "/usr/local/lib/python3.12/site-packages/rest_framework/views.py", line 486, in raise_uncaught_exception
    raise exc
  File "/usr/local/lib/python3.12/site-packages/rest_framework/views.py", line 503, in dispatch
    self.initial(request, *args, **kwargs)
  File "/usr/local/lib/python3.12/site-packages/rest_framework/views.py", line 420, in initial
    self.perform_authentication(request)
  File "/usr/local/lib/python3.12/site-packages/rest_framework/views.py", line 330, in perform_authentication
    request.user
  File "/usr/local/lib/python3.12/site-packages/rest_framework/request.py", line 232, in user
    self._authenticate()
  File "/usr/local/lib/python3.12/site-packages/rest_framework/request.py", line 385, in _authenticate
    user_auth_tuple = authenticator.authenticate(self)
                      ^^^^^^^^^^^^^^^^^^^^^^^^^^^^^^^^
  File "/usr/local/lib/python3.12/site-packages/rest_framework/authentication.py", line 127, in authenticate
    if not user or not user.is_active:
           ^^^^
  File "/usr/local/lib/python3.12/site-packages/django/utils/functional.py", line 251, in inner
    self._setup()
  File "/usr/local/lib/python3.12/site-packages/django/utils/functional.py", line 404, in _setup
    self._wrapped = self._setupfunc()
                    ^^^^^^^^^^^^^^^^^
  File "/usr/local/lib/python3.12/site-packages/django/contrib/auth/middleware.py", line 40, in <lambda>
    request.user = SimpleLazyObject(lambda: get_user(request))
                                            ^^^^^^^^^^^^^^^^^
  File "/usr/local/lib/python3.12/site-packages/django/contrib/auth/middleware.py", line 20, in get_user
    request._cached_user = auth.get_user(request)
                           ^^^^^^^^^^^^^^^^^^^^^^
  File "/usr/local/lib/python3.12/site-packages/django/contrib/auth/__init__.py", line 304, in get_user
    user_id = _get_user_session_key(request)
              ^^^^^^^^^^^^^^^^^^^^^^^^^^^^^^
  File "/usr/local/lib/python3.12/site-packages/django/contrib/auth/__init__.py", line 95, in _get_user_session_key
    return get_user_model()._meta.pk.to_python(request.session[SESSION_KEY])
                                               ~~~~~~~~~~~~~~~^^^^^^^^^^^^^
  File "/usr/local/lib/python3.12/site-packages/django/contrib/sessions/backends/base.py", line 55, in __getitem__
    return self._session[key]
           ^^^^^^^^^^^^^
  File "/usr/local/lib/python3.12/site-packages/django/contrib/sessions/backends/base.py", line 249, in _get_session
    self._session_cache = self.load()
                          ^^^^^^^^^^^
  File "/usr/local/lib/python3.12/site-packages/django/contrib/sessions/backends/db.py", line 55, in load
    s = self._get_session_from_db()
        ^^^^^^^^^^^^^^^^^^^^^^^^^^^
  File "/usr/local/lib/python3.12/site-packages/django/contrib/sessions/backends/db.py", line 34, in _get_session_from_db
    return self.model.objects.get(
           ^^^^^^^^^^^^^^^^^^^^^^^
  File "/usr/local/lib/python3.12/site-packages/django/db/models/manager.py", line 87, in manager_method
    return getattr(self.get_queryset(), name)(*args, **kwargs)
           ^^^^^^^^^^^^^^^^^^^^^^^^^^^^^^^^^^^^^^^^^^^^^^^^^^^
  File "/usr/local/lib/python3.12/site-packages/django/db/models/query.py", line 629, in get
    num = len(clone)
          ^^^^^^^^^^
  File "/usr/local/lib/python3.12/site-packages/django/db/models/query.py", line 366, in __len__
    self._fetch_all()
  File "/usr/local/lib/python3.12/site-packages/django/db/models/query.py", line 1949, in _fetch_all
    self._result_cache = list(self._iterable_class(self))
                         ^^^^^^^^^^^^^^^^^^^^^^^^^^^^^^^^
  File "/usr/local/lib/python3.12/site-packages/django/db/models/query.py", line 91, in __iter__
    results = compiler.execute_sql(
              ^^^^^^^^^^^^^^^^^^^^^
  File "/usr/local/lib/python3.12/site-packages/django/db/models/sql/compiler.py", line 1623, in execute_sql
    cursor.execute(sql, params)
  File "/usr/local/lib/python3.12/site-packages/django/db/backends/utils.py", line 122, in execute
    return super().execute(sql, params)
           ^^^^^^^^^^^^^^^^^^^^^^^^^^^^
  File "/usr/local/lib/python3.12/site-packages/django/db/backends/utils.py", line 79, in execute
    return self._execute_with_wrappers(
           ^^^^^^^^^^^^^^^^^^^^^^^^^^^^
  File "/usr/local/lib/python3.12/site-packages/django/db/backends/utils.py", line 92, in _execute_with_wrappers
    return executor(sql, params, many, context)
           ^^^^^^^^^^^^^^^^^^^^^^^^^^^^^^^^^^^^
  File "/usr/local/lib/python3.12/site-packages/django/db/backends/utils.py", line 100, in _execute
    with self.db.wrap_database_errors:
         ^^^^^^^^^^^^^^^^^^^^^^^^^^^^
  File "/usr/local/lib/python3.12/site-packages/django/db/utils.py", line 91, in __exit__
    raise dj_exc_value.with_traceback(traceback) from exc_value
  File "/usr/local/lib/python3.12/site-packages/django/db/backends/utils.py", line 105, in _execute
    return self.cursor.execute(sql, params)
           ^^^^^^^^^^^^^^^^^^^^^^^^^^^^^^^^
django.db.utils.ProgrammingError: relation "django_session" does not exist
LINE 1: ...ession_data", "django_session"."expire_date" FROM "django_se...
                                                             ^

[2025-09-22 14:41:34,215] ERROR django.server:213 — "GET / HTTP/1.1" 500 211995
[2025-09-22 14:41:34,795] ERROR django.request:253 — Internal Server Error: /
Traceback (most recent call last):
  File "/usr/local/lib/python3.12/site-packages/django/contrib/sessions/backends/base.py", line 244, in _get_session
    return self._session_cache
           ^^^^^^^^^^^^^^^^^^^
AttributeError: 'SessionStore' object has no attribute '_session_cache'

During handling of the above exception, another exception occurred:

Traceback (most recent call last):
  File "/usr/local/lib/python3.12/site-packages/django/db/backends/utils.py", line 105, in _execute
    return self.cursor.execute(sql, params)
           ^^^^^^^^^^^^^^^^^^^^^^^^^^^^^^^^
psycopg2.errors.UndefinedTable: relation "django_session" does not exist
LINE 1: ...ession_data", "django_session"."expire_date" FROM "django_se...
                                                             ^


The above exception was the direct cause of the following exception:

Traceback (most recent call last):
  File "/usr/local/lib/python3.12/site-packages/django/core/handlers/exception.py", line 55, in inner
    response = get_response(request)
               ^^^^^^^^^^^^^^^^^^^^^
  File "/usr/local/lib/python3.12/site-packages/django/core/handlers/base.py", line 197, in _get_response
    response = wrapped_callback(request, *callback_args, **callback_kwargs)
               ^^^^^^^^^^^^^^^^^^^^^^^^^^^^^^^^^^^^^^^^^^^^^^^^^^^^^^^^^^^^
  File "/usr/local/lib/python3.12/site-packages/django/views/decorators/csrf.py", line 65, in _view_wrapper
    return view_func(request, *args, **kwargs)
           ^^^^^^^^^^^^^^^^^^^^^^^^^^^^^^^^^^^
  File "/usr/local/lib/python3.12/site-packages/django/views/generic/base.py", line 105, in view
    return self.dispatch(request, *args, **kwargs)
           ^^^^^^^^^^^^^^^^^^^^^^^^^^^^^^^^^^^^^^^
  File "/usr/local/lib/python3.12/site-packages/rest_framework/views.py", line 515, in dispatch
    response = self.handle_exception(exc)
               ^^^^^^^^^^^^^^^^^^^^^^^^^^
  File "/usr/local/lib/python3.12/site-packages/rest_framework/views.py", line 475, in handle_exception
    self.raise_uncaught_exception(exc)
  File "/usr/local/lib/python3.12/site-packages/rest_framework/views.py", line 486, in raise_uncaught_exception
    raise exc
  File "/usr/local/lib/python3.12/site-packages/rest_framework/views.py", line 503, in dispatch
    self.initial(request, *args, **kwargs)
  File "/usr/local/lib/python3.12/site-packages/rest_framework/views.py", line 420, in initial
    self.perform_authentication(request)
  File "/usr/local/lib/python3.12/site-packages/rest_framework/views.py", line 330, in perform_authentication
    request.user
  File "/usr/local/lib/python3.12/site-packages/rest_framework/request.py", line 232, in user
    self._authenticate()
  File "/usr/local/lib/python3.12/site-packages/rest_framework/request.py", line 385, in _authenticate
    user_auth_tuple = authenticator.authenticate(self)
                      ^^^^^^^^^^^^^^^^^^^^^^^^^^^^^^^^
  File "/usr/local/lib/python3.12/site-packages/rest_framework/authentication.py", line 127, in authenticate
    if not user or not user.is_active:
           ^^^^
  File "/usr/local/lib/python3.12/site-packages/django/utils/functional.py", line 251, in inner
    self._setup()
  File "/usr/local/lib/python3.12/site-packages/django/utils/functional.py", line 404, in _setup
    self._wrapped = self._setupfunc()
                    ^^^^^^^^^^^^^^^^^
  File "/usr/local/lib/python3.12/site-packages/django/contrib/auth/middleware.py", line 40, in <lambda>
    request.user = SimpleLazyObject(lambda: get_user(request))
                                            ^^^^^^^^^^^^^^^^^
  File "/usr/local/lib/python3.12/site-packages/django/contrib/auth/middleware.py", line 20, in get_user
    request._cached_user = auth.get_user(request)
                           ^^^^^^^^^^^^^^^^^^^^^^
  File "/usr/local/lib/python3.12/site-packages/django/contrib/auth/__init__.py", line 304, in get_user
    user_id = _get_user_session_key(request)
              ^^^^^^^^^^^^^^^^^^^^^^^^^^^^^^
  File "/usr/local/lib/python3.12/site-packages/django/contrib/auth/__init__.py", line 95, in _get_user_session_key
    return get_user_model()._meta.pk.to_python(request.session[SESSION_KEY])
                                               ~~~~~~~~~~~~~~~^^^^^^^^^^^^^
  File "/usr/local/lib/python3.12/site-packages/django/contrib/sessions/backends/base.py", line 55, in __getitem__
    return self._session[key]
           ^^^^^^^^^^^^^
  File "/usr/local/lib/python3.12/site-packages/django/contrib/sessions/backends/base.py", line 249, in _get_session
    self._session_cache = self.load()
                          ^^^^^^^^^^^
  File "/usr/local/lib/python3.12/site-packages/django/contrib/sessions/backends/db.py", line 55, in load
    s = self._get_session_from_db()
        ^^^^^^^^^^^^^^^^^^^^^^^^^^^
  File "/usr/local/lib/python3.12/site-packages/django/contrib/sessions/backends/db.py", line 34, in _get_session_from_db
    return self.model.objects.get(
           ^^^^^^^^^^^^^^^^^^^^^^^
  File "/usr/local/lib/python3.12/site-packages/django/db/models/manager.py", line 87, in manager_method
    return getattr(self.get_queryset(), name)(*args, **kwargs)
           ^^^^^^^^^^^^^^^^^^^^^^^^^^^^^^^^^^^^^^^^^^^^^^^^^^^
  File "/usr/local/lib/python3.12/site-packages/django/db/models/query.py", line 629, in get
    num = len(clone)
          ^^^^^^^^^^
  File "/usr/local/lib/python3.12/site-packages/django/db/models/query.py", line 366, in __len__
    self._fetch_all()
  File "/usr/local/lib/python3.12/site-packages/django/db/models/query.py", line 1949, in _fetch_all
    self._result_cache = list(self._iterable_class(self))
                         ^^^^^^^^^^^^^^^^^^^^^^^^^^^^^^^^
  File "/usr/local/lib/python3.12/site-packages/django/db/models/query.py", line 91, in __iter__
    results = compiler.execute_sql(
              ^^^^^^^^^^^^^^^^^^^^^
  File "/usr/local/lib/python3.12/site-packages/django/db/models/sql/compiler.py", line 1623, in execute_sql
    cursor.execute(sql, params)
  File "/usr/local/lib/python3.12/site-packages/django/db/backends/utils.py", line 122, in execute
    return super().execute(sql, params)
           ^^^^^^^^^^^^^^^^^^^^^^^^^^^^
  File "/usr/local/lib/python3.12/site-packages/django/db/backends/utils.py", line 79, in execute
    return self._execute_with_wrappers(
           ^^^^^^^^^^^^^^^^^^^^^^^^^^^^
  File "/usr/local/lib/python3.12/site-packages/django/db/backends/utils.py", line 92, in _execute_with_wrappers
    return executor(sql, params, many, context)
           ^^^^^^^^^^^^^^^^^^^^^^^^^^^^^^^^^^^^
  File "/usr/local/lib/python3.12/site-packages/django/db/backends/utils.py", line 100, in _execute
    with self.db.wrap_database_errors:
         ^^^^^^^^^^^^^^^^^^^^^^^^^^^^
  File "/usr/local/lib/python3.12/site-packages/django/db/utils.py", line 91, in __exit__
    raise dj_exc_value.with_traceback(traceback) from exc_value
  File "/usr/local/lib/python3.12/site-packages/django/db/backends/utils.py", line 105, in _execute
    return self.cursor.execute(sql, params)
           ^^^^^^^^^^^^^^^^^^^^^^^^^^^^^^^^
django.db.utils.ProgrammingError: relation "django_session" does not exist
LINE 1: ...ession_data", "django_session"."expire_date" FROM "django_se...
                                                             ^

[2025-09-22 14:41:34,800] ERROR django.server:213 — "GET / HTTP/1.1" 500 211995
[2025-09-22 14:41:39,367] INFO django.utils.autoreload:667 — Watching for file changes with StatReloader
[2025-09-22 14:41:40,026] ERROR django.request:253 — Internal Server Error: /
Traceback (most recent call last):
  File "/usr/local/lib/python3.12/site-packages/django/contrib/sessions/backends/base.py", line 244, in _get_session
    return self._session_cache
           ^^^^^^^^^^^^^^^^^^^
AttributeError: 'SessionStore' object has no attribute '_session_cache'

During handling of the above exception, another exception occurred:

Traceback (most recent call last):
  File "/usr/local/lib/python3.12/site-packages/django/db/backends/utils.py", line 105, in _execute
    return self.cursor.execute(sql, params)
           ^^^^^^^^^^^^^^^^^^^^^^^^^^^^^^^^
psycopg2.errors.UndefinedTable: relation "django_session" does not exist
LINE 1: ...ession_data", "django_session"."expire_date" FROM "django_se...
                                                             ^


The above exception was the direct cause of the following exception:

Traceback (most recent call last):
  File "/usr/local/lib/python3.12/site-packages/django/core/handlers/exception.py", line 55, in inner
    response = get_response(request)
               ^^^^^^^^^^^^^^^^^^^^^
  File "/usr/local/lib/python3.12/site-packages/django/core/handlers/base.py", line 197, in _get_response
    response = wrapped_callback(request, *callback_args, **callback_kwargs)
               ^^^^^^^^^^^^^^^^^^^^^^^^^^^^^^^^^^^^^^^^^^^^^^^^^^^^^^^^^^^^
  File "/usr/local/lib/python3.12/site-packages/django/views/decorators/csrf.py", line 65, in _view_wrapper
    return view_func(request, *args, **kwargs)
           ^^^^^^^^^^^^^^^^^^^^^^^^^^^^^^^^^^^
  File "/usr/local/lib/python3.12/site-packages/django/views/generic/base.py", line 105, in view
    return self.dispatch(request, *args, **kwargs)
           ^^^^^^^^^^^^^^^^^^^^^^^^^^^^^^^^^^^^^^^
  File "/usr/local/lib/python3.12/site-packages/rest_framework/views.py", line 515, in dispatch
    response = self.handle_exception(exc)
               ^^^^^^^^^^^^^^^^^^^^^^^^^^
  File "/usr/local/lib/python3.12/site-packages/rest_framework/views.py", line 475, in handle_exception
    self.raise_uncaught_exception(exc)
  File "/usr/local/lib/python3.12/site-packages/rest_framework/views.py", line 486, in raise_uncaught_exception
    raise exc
  File "/usr/local/lib/python3.12/site-packages/rest_framework/views.py", line 503, in dispatch
    self.initial(request, *args, **kwargs)
  File "/usr/local/lib/python3.12/site-packages/rest_framework/views.py", line 420, in initial
    self.perform_authentication(request)
  File "/usr/local/lib/python3.12/site-packages/rest_framework/views.py", line 330, in perform_authentication
    request.user
  File "/usr/local/lib/python3.12/site-packages/rest_framework/request.py", line 232, in user
    self._authenticate()
  File "/usr/local/lib/python3.12/site-packages/rest_framework/request.py", line 385, in _authenticate
    user_auth_tuple = authenticator.authenticate(self)
                      ^^^^^^^^^^^^^^^^^^^^^^^^^^^^^^^^
  File "/usr/local/lib/python3.12/site-packages/rest_framework/authentication.py", line 127, in authenticate
    if not user or not user.is_active:
           ^^^^
  File "/usr/local/lib/python3.12/site-packages/django/utils/functional.py", line 251, in inner
    self._setup()
  File "/usr/local/lib/python3.12/site-packages/django/utils/functional.py", line 404, in _setup
    self._wrapped = self._setupfunc()
                    ^^^^^^^^^^^^^^^^^
  File "/usr/local/lib/python3.12/site-packages/django/contrib/auth/middleware.py", line 40, in <lambda>
    request.user = SimpleLazyObject(lambda: get_user(request))
                                            ^^^^^^^^^^^^^^^^^
  File "/usr/local/lib/python3.12/site-packages/django/contrib/auth/middleware.py", line 20, in get_user
    request._cached_user = auth.get_user(request)
                           ^^^^^^^^^^^^^^^^^^^^^^
  File "/usr/local/lib/python3.12/site-packages/django/contrib/auth/__init__.py", line 304, in get_user
    user_id = _get_user_session_key(request)
              ^^^^^^^^^^^^^^^^^^^^^^^^^^^^^^
  File "/usr/local/lib/python3.12/site-packages/django/contrib/auth/__init__.py", line 95, in _get_user_session_key
    return get_user_model()._meta.pk.to_python(request.session[SESSION_KEY])
                                               ~~~~~~~~~~~~~~~^^^^^^^^^^^^^
  File "/usr/local/lib/python3.12/site-packages/django/contrib/sessions/backends/base.py", line 55, in __getitem__
    return self._session[key]
           ^^^^^^^^^^^^^
  File "/usr/local/lib/python3.12/site-packages/django/contrib/sessions/backends/base.py", line 249, in _get_session
    self._session_cache = self.load()
                          ^^^^^^^^^^^
  File "/usr/local/lib/python3.12/site-packages/django/contrib/sessions/backends/db.py", line 55, in load
    s = self._get_session_from_db()
        ^^^^^^^^^^^^^^^^^^^^^^^^^^^
  File "/usr/local/lib/python3.12/site-packages/django/contrib/sessions/backends/db.py", line 34, in _get_session_from_db
    return self.model.objects.get(
           ^^^^^^^^^^^^^^^^^^^^^^^
  File "/usr/local/lib/python3.12/site-packages/django/db/models/manager.py", line 87, in manager_method
    return getattr(self.get_queryset(), name)(*args, **kwargs)
           ^^^^^^^^^^^^^^^^^^^^^^^^^^^^^^^^^^^^^^^^^^^^^^^^^^^
  File "/usr/local/lib/python3.12/site-packages/django/db/models/query.py", line 629, in get
    num = len(clone)
          ^^^^^^^^^^
  File "/usr/local/lib/python3.12/site-packages/django/db/models/query.py", line 366, in __len__
    self._fetch_all()
  File "/usr/local/lib/python3.12/site-packages/django/db/models/query.py", line 1949, in _fetch_all
    self._result_cache = list(self._iterable_class(self))
                         ^^^^^^^^^^^^^^^^^^^^^^^^^^^^^^^^
  File "/usr/local/lib/python3.12/site-packages/django/db/models/query.py", line 91, in __iter__
    results = compiler.execute_sql(
              ^^^^^^^^^^^^^^^^^^^^^
  File "/usr/local/lib/python3.12/site-packages/django/db/models/sql/compiler.py", line 1623, in execute_sql
    cursor.execute(sql, params)
  File "/usr/local/lib/python3.12/site-packages/django/db/backends/utils.py", line 122, in execute
    return super().execute(sql, params)
           ^^^^^^^^^^^^^^^^^^^^^^^^^^^^
  File "/usr/local/lib/python3.12/site-packages/django/db/backends/utils.py", line 79, in execute
    return self._execute_with_wrappers(
           ^^^^^^^^^^^^^^^^^^^^^^^^^^^^
  File "/usr/local/lib/python3.12/site-packages/django/db/backends/utils.py", line 92, in _execute_with_wrappers
    return executor(sql, params, many, context)
           ^^^^^^^^^^^^^^^^^^^^^^^^^^^^^^^^^^^^
  File "/usr/local/lib/python3.12/site-packages/django/db/backends/utils.py", line 100, in _execute
    with self.db.wrap_database_errors:
         ^^^^^^^^^^^^^^^^^^^^^^^^^^^^
  File "/usr/local/lib/python3.12/site-packages/django/db/utils.py", line 91, in __exit__
    raise dj_exc_value.with_traceback(traceback) from exc_value
  File "/usr/local/lib/python3.12/site-packages/django/db/backends/utils.py", line 105, in _execute
    return self.cursor.execute(sql, params)
           ^^^^^^^^^^^^^^^^^^^^^^^^^^^^^^^^
django.db.utils.ProgrammingError: relation "django_session" does not exist
LINE 1: ...ession_data", "django_session"."expire_date" FROM "django_se...
                                                             ^

[2025-09-22 14:41:40,033] ERROR django.server:213 — "GET / HTTP/1.1" 500 211995
[2025-09-22 14:41:40,785] ERROR django.request:253 — Internal Server Error: /
Traceback (most recent call last):
  File "/usr/local/lib/python3.12/site-packages/django/contrib/sessions/backends/base.py", line 244, in _get_session
    return self._session_cache
           ^^^^^^^^^^^^^^^^^^^
AttributeError: 'SessionStore' object has no attribute '_session_cache'

During handling of the above exception, another exception occurred:

Traceback (most recent call last):
  File "/usr/local/lib/python3.12/site-packages/django/db/backends/utils.py", line 105, in _execute
    return self.cursor.execute(sql, params)
           ^^^^^^^^^^^^^^^^^^^^^^^^^^^^^^^^
psycopg2.errors.UndefinedTable: relation "django_session" does not exist
LINE 1: ...ession_data", "django_session"."expire_date" FROM "django_se...
                                                             ^


The above exception was the direct cause of the following exception:

Traceback (most recent call last):
  File "/usr/local/lib/python3.12/site-packages/django/core/handlers/exception.py", line 55, in inner
    response = get_response(request)
               ^^^^^^^^^^^^^^^^^^^^^
  File "/usr/local/lib/python3.12/site-packages/django/core/handlers/base.py", line 197, in _get_response
    response = wrapped_callback(request, *callback_args, **callback_kwargs)
               ^^^^^^^^^^^^^^^^^^^^^^^^^^^^^^^^^^^^^^^^^^^^^^^^^^^^^^^^^^^^
  File "/usr/local/lib/python3.12/site-packages/django/views/decorators/csrf.py", line 65, in _view_wrapper
    return view_func(request, *args, **kwargs)
           ^^^^^^^^^^^^^^^^^^^^^^^^^^^^^^^^^^^
  File "/usr/local/lib/python3.12/site-packages/django/views/generic/base.py", line 105, in view
    return self.dispatch(request, *args, **kwargs)
           ^^^^^^^^^^^^^^^^^^^^^^^^^^^^^^^^^^^^^^^
  File "/usr/local/lib/python3.12/site-packages/rest_framework/views.py", line 515, in dispatch
    response = self.handle_exception(exc)
               ^^^^^^^^^^^^^^^^^^^^^^^^^^
  File "/usr/local/lib/python3.12/site-packages/rest_framework/views.py", line 475, in handle_exception
    self.raise_uncaught_exception(exc)
  File "/usr/local/lib/python3.12/site-packages/rest_framework/views.py", line 486, in raise_uncaught_exception
    raise exc
  File "/usr/local/lib/python3.12/site-packages/rest_framework/views.py", line 503, in dispatch
    self.initial(request, *args, **kwargs)
  File "/usr/local/lib/python3.12/site-packages/rest_framework/views.py", line 420, in initial
    self.perform_authentication(request)
  File "/usr/local/lib/python3.12/site-packages/rest_framework/views.py", line 330, in perform_authentication
    request.user
  File "/usr/local/lib/python3.12/site-packages/rest_framework/request.py", line 232, in user
    self._authenticate()
  File "/usr/local/lib/python3.12/site-packages/rest_framework/request.py", line 385, in _authenticate
    user_auth_tuple = authenticator.authenticate(self)
                      ^^^^^^^^^^^^^^^^^^^^^^^^^^^^^^^^
  File "/usr/local/lib/python3.12/site-packages/rest_framework/authentication.py", line 127, in authenticate
    if not user or not user.is_active:
           ^^^^
  File "/usr/local/lib/python3.12/site-packages/django/utils/functional.py", line 251, in inner
    self._setup()
  File "/usr/local/lib/python3.12/site-packages/django/utils/functional.py", line 404, in _setup
    self._wrapped = self._setupfunc()
                    ^^^^^^^^^^^^^^^^^
  File "/usr/local/lib/python3.12/site-packages/django/contrib/auth/middleware.py", line 40, in <lambda>
    request.user = SimpleLazyObject(lambda: get_user(request))
                                            ^^^^^^^^^^^^^^^^^
  File "/usr/local/lib/python3.12/site-packages/django/contrib/auth/middleware.py", line 20, in get_user
    request._cached_user = auth.get_user(request)
                           ^^^^^^^^^^^^^^^^^^^^^^
  File "/usr/local/lib/python3.12/site-packages/django/contrib/auth/__init__.py", line 304, in get_user
    user_id = _get_user_session_key(request)
              ^^^^^^^^^^^^^^^^^^^^^^^^^^^^^^
  File "/usr/local/lib/python3.12/site-packages/django/contrib/auth/__init__.py", line 95, in _get_user_session_key
    return get_user_model()._meta.pk.to_python(request.session[SESSION_KEY])
                                               ~~~~~~~~~~~~~~~^^^^^^^^^^^^^
  File "/usr/local/lib/python3.12/site-packages/django/contrib/sessions/backends/base.py", line 55, in __getitem__
    return self._session[key]
           ^^^^^^^^^^^^^
  File "/usr/local/lib/python3.12/site-packages/django/contrib/sessions/backends/base.py", line 249, in _get_session
    self._session_cache = self.load()
                          ^^^^^^^^^^^
  File "/usr/local/lib/python3.12/site-packages/django/contrib/sessions/backends/db.py", line 55, in load
    s = self._get_session_from_db()
        ^^^^^^^^^^^^^^^^^^^^^^^^^^^
  File "/usr/local/lib/python3.12/site-packages/django/contrib/sessions/backends/db.py", line 34, in _get_session_from_db
    return self.model.objects.get(
           ^^^^^^^^^^^^^^^^^^^^^^^
  File "/usr/local/lib/python3.12/site-packages/django/db/models/manager.py", line 87, in manager_method
    return getattr(self.get_queryset(), name)(*args, **kwargs)
           ^^^^^^^^^^^^^^^^^^^^^^^^^^^^^^^^^^^^^^^^^^^^^^^^^^^
  File "/usr/local/lib/python3.12/site-packages/django/db/models/query.py", line 629, in get
    num = len(clone)
          ^^^^^^^^^^
  File "/usr/local/lib/python3.12/site-packages/django/db/models/query.py", line 366, in __len__
    self._fetch_all()
  File "/usr/local/lib/python3.12/site-packages/django/db/models/query.py", line 1949, in _fetch_all
    self._result_cache = list(self._iterable_class(self))
                         ^^^^^^^^^^^^^^^^^^^^^^^^^^^^^^^^
  File "/usr/local/lib/python3.12/site-packages/django/db/models/query.py", line 91, in __iter__
    results = compiler.execute_sql(
              ^^^^^^^^^^^^^^^^^^^^^
  File "/usr/local/lib/python3.12/site-packages/django/db/models/sql/compiler.py", line 1623, in execute_sql
    cursor.execute(sql, params)
  File "/usr/local/lib/python3.12/site-packages/django/db/backends/utils.py", line 122, in execute
    return super().execute(sql, params)
           ^^^^^^^^^^^^^^^^^^^^^^^^^^^^
  File "/usr/local/lib/python3.12/site-packages/django/db/backends/utils.py", line 79, in execute
    return self._execute_with_wrappers(
           ^^^^^^^^^^^^^^^^^^^^^^^^^^^^
  File "/usr/local/lib/python3.12/site-packages/django/db/backends/utils.py", line 92, in _execute_with_wrappers
    return executor(sql, params, many, context)
           ^^^^^^^^^^^^^^^^^^^^^^^^^^^^^^^^^^^^
  File "/usr/local/lib/python3.12/site-packages/django/db/backends/utils.py", line 100, in _execute
    with self.db.wrap_database_errors:
         ^^^^^^^^^^^^^^^^^^^^^^^^^^^^
  File "/usr/local/lib/python3.12/site-packages/django/db/utils.py", line 91, in __exit__
    raise dj_exc_value.with_traceback(traceback) from exc_value
  File "/usr/local/lib/python3.12/site-packages/django/db/backends/utils.py", line 105, in _execute
    return self.cursor.execute(sql, params)
           ^^^^^^^^^^^^^^^^^^^^^^^^^^^^^^^^
django.db.utils.ProgrammingError: relation "django_session" does not exist
LINE 1: ...ession_data", "django_session"."expire_date" FROM "django_se...
                                                             ^

[2025-09-22 14:41:40,789] ERROR django.server:213 — "GET / HTTP/1.1" 500 211995
[2025-09-22 14:42:29,925] INFO django.server:213 — "GET /user/logout HTTP/1.1" 301 0
[2025-09-22 14:42:29,993] ERROR django.request:253 — Internal Server Error: /user/logout/
Traceback (most recent call last):
  File "/usr/local/lib/python3.12/site-packages/django/contrib/sessions/backends/base.py", line 244, in _get_session
    return self._session_cache
           ^^^^^^^^^^^^^^^^^^^
AttributeError: 'SessionStore' object has no attribute '_session_cache'

During handling of the above exception, another exception occurred:

Traceback (most recent call last):
  File "/usr/local/lib/python3.12/site-packages/django/db/backends/utils.py", line 105, in _execute
    return self.cursor.execute(sql, params)
           ^^^^^^^^^^^^^^^^^^^^^^^^^^^^^^^^
psycopg2.errors.UndefinedTable: relation "django_session" does not exist
LINE 1: ...ession_data", "django_session"."expire_date" FROM "django_se...
                                                             ^


The above exception was the direct cause of the following exception:

Traceback (most recent call last):
  File "/usr/local/lib/python3.12/site-packages/django/core/handlers/exception.py", line 55, in inner
    response = get_response(request)
               ^^^^^^^^^^^^^^^^^^^^^
  File "/usr/local/lib/python3.12/site-packages/django/core/handlers/base.py", line 197, in _get_response
    response = wrapped_callback(request, *callback_args, **callback_kwargs)
               ^^^^^^^^^^^^^^^^^^^^^^^^^^^^^^^^^^^^^^^^^^^^^^^^^^^^^^^^^^^^
  File "/usr/local/lib/python3.12/site-packages/django/views/decorators/csrf.py", line 65, in _view_wrapper
    return view_func(request, *args, **kwargs)
           ^^^^^^^^^^^^^^^^^^^^^^^^^^^^^^^^^^^
  File "/usr/local/lib/python3.12/site-packages/django/views/generic/base.py", line 105, in view
    return self.dispatch(request, *args, **kwargs)
           ^^^^^^^^^^^^^^^^^^^^^^^^^^^^^^^^^^^^^^^
  File "/usr/local/lib/python3.12/site-packages/rest_framework/views.py", line 515, in dispatch
    response = self.handle_exception(exc)
               ^^^^^^^^^^^^^^^^^^^^^^^^^^
  File "/usr/local/lib/python3.12/site-packages/rest_framework/views.py", line 475, in handle_exception
    self.raise_uncaught_exception(exc)
  File "/usr/local/lib/python3.12/site-packages/rest_framework/views.py", line 486, in raise_uncaught_exception
    raise exc
  File "/usr/local/lib/python3.12/site-packages/rest_framework/views.py", line 503, in dispatch
    self.initial(request, *args, **kwargs)
  File "/usr/local/lib/python3.12/site-packages/rest_framework/views.py", line 420, in initial
    self.perform_authentication(request)
  File "/usr/local/lib/python3.12/site-packages/rest_framework/views.py", line 330, in perform_authentication
    request.user
  File "/usr/local/lib/python3.12/site-packages/rest_framework/request.py", line 232, in user
    self._authenticate()
  File "/usr/local/lib/python3.12/site-packages/rest_framework/request.py", line 385, in _authenticate
    user_auth_tuple = authenticator.authenticate(self)
                      ^^^^^^^^^^^^^^^^^^^^^^^^^^^^^^^^
  File "/usr/local/lib/python3.12/site-packages/rest_framework/authentication.py", line 127, in authenticate
    if not user or not user.is_active:
           ^^^^
  File "/usr/local/lib/python3.12/site-packages/django/utils/functional.py", line 251, in inner
    self._setup()
  File "/usr/local/lib/python3.12/site-packages/django/utils/functional.py", line 404, in _setup
    self._wrapped = self._setupfunc()
                    ^^^^^^^^^^^^^^^^^
  File "/usr/local/lib/python3.12/site-packages/django/contrib/auth/middleware.py", line 40, in <lambda>
    request.user = SimpleLazyObject(lambda: get_user(request))
                                            ^^^^^^^^^^^^^^^^^
  File "/usr/local/lib/python3.12/site-packages/django/contrib/auth/middleware.py", line 20, in get_user
    request._cached_user = auth.get_user(request)
                           ^^^^^^^^^^^^^^^^^^^^^^
  File "/usr/local/lib/python3.12/site-packages/django/contrib/auth/__init__.py", line 304, in get_user
    user_id = _get_user_session_key(request)
              ^^^^^^^^^^^^^^^^^^^^^^^^^^^^^^
  File "/usr/local/lib/python3.12/site-packages/django/contrib/auth/__init__.py", line 95, in _get_user_session_key
    return get_user_model()._meta.pk.to_python(request.session[SESSION_KEY])
                                               ~~~~~~~~~~~~~~~^^^^^^^^^^^^^
  File "/usr/local/lib/python3.12/site-packages/django/contrib/sessions/backends/base.py", line 55, in __getitem__
    return self._session[key]
           ^^^^^^^^^^^^^
  File "/usr/local/lib/python3.12/site-packages/django/contrib/sessions/backends/base.py", line 249, in _get_session
    self._session_cache = self.load()
                          ^^^^^^^^^^^
  File "/usr/local/lib/python3.12/site-packages/django/contrib/sessions/backends/db.py", line 55, in load
    s = self._get_session_from_db()
        ^^^^^^^^^^^^^^^^^^^^^^^^^^^
  File "/usr/local/lib/python3.12/site-packages/django/contrib/sessions/backends/db.py", line 34, in _get_session_from_db
    return self.model.objects.get(
           ^^^^^^^^^^^^^^^^^^^^^^^
  File "/usr/local/lib/python3.12/site-packages/django/db/models/manager.py", line 87, in manager_method
    return getattr(self.get_queryset(), name)(*args, **kwargs)
           ^^^^^^^^^^^^^^^^^^^^^^^^^^^^^^^^^^^^^^^^^^^^^^^^^^^
  File "/usr/local/lib/python3.12/site-packages/django/db/models/query.py", line 629, in get
    num = len(clone)
          ^^^^^^^^^^
  File "/usr/local/lib/python3.12/site-packages/django/db/models/query.py", line 366, in __len__
    self._fetch_all()
  File "/usr/local/lib/python3.12/site-packages/django/db/models/query.py", line 1949, in _fetch_all
    self._result_cache = list(self._iterable_class(self))
                         ^^^^^^^^^^^^^^^^^^^^^^^^^^^^^^^^
  File "/usr/local/lib/python3.12/site-packages/django/db/models/query.py", line 91, in __iter__
    results = compiler.execute_sql(
              ^^^^^^^^^^^^^^^^^^^^^
  File "/usr/local/lib/python3.12/site-packages/django/db/models/sql/compiler.py", line 1623, in execute_sql
    cursor.execute(sql, params)
  File "/usr/local/lib/python3.12/site-packages/django/db/backends/utils.py", line 122, in execute
    return super().execute(sql, params)
           ^^^^^^^^^^^^^^^^^^^^^^^^^^^^
  File "/usr/local/lib/python3.12/site-packages/django/db/backends/utils.py", line 79, in execute
    return self._execute_with_wrappers(
           ^^^^^^^^^^^^^^^^^^^^^^^^^^^^
  File "/usr/local/lib/python3.12/site-packages/django/db/backends/utils.py", line 92, in _execute_with_wrappers
    return executor(sql, params, many, context)
           ^^^^^^^^^^^^^^^^^^^^^^^^^^^^^^^^^^^^
  File "/usr/local/lib/python3.12/site-packages/django/db/backends/utils.py", line 100, in _execute
    with self.db.wrap_database_errors:
         ^^^^^^^^^^^^^^^^^^^^^^^^^^^^
  File "/usr/local/lib/python3.12/site-packages/django/db/utils.py", line 91, in __exit__
    raise dj_exc_value.with_traceback(traceback) from exc_value
  File "/usr/local/lib/python3.12/site-packages/django/db/backends/utils.py", line 105, in _execute
    return self.cursor.execute(sql, params)
           ^^^^^^^^^^^^^^^^^^^^^^^^^^^^^^^^
django.db.utils.ProgrammingError: relation "django_session" does not exist
LINE 1: ...ession_data", "django_session"."expire_date" FROM "django_se...
                                                             ^

[2025-09-22 14:42:29,997] ERROR django.server:213 — "GET /user/logout/ HTTP/1.1" 500 212299
[2025-09-22 14:42:32,660] ERROR django.request:253 — Internal Server Error: /
Traceback (most recent call last):
  File "/usr/local/lib/python3.12/site-packages/django/contrib/sessions/backends/base.py", line 244, in _get_session
    return self._session_cache
           ^^^^^^^^^^^^^^^^^^^
AttributeError: 'SessionStore' object has no attribute '_session_cache'

During handling of the above exception, another exception occurred:

Traceback (most recent call last):
  File "/usr/local/lib/python3.12/site-packages/django/db/backends/utils.py", line 105, in _execute
    return self.cursor.execute(sql, params)
           ^^^^^^^^^^^^^^^^^^^^^^^^^^^^^^^^
psycopg2.errors.UndefinedTable: relation "django_session" does not exist
LINE 1: ...ession_data", "django_session"."expire_date" FROM "django_se...
                                                             ^


The above exception was the direct cause of the following exception:

Traceback (most recent call last):
  File "/usr/local/lib/python3.12/site-packages/django/core/handlers/exception.py", line 55, in inner
    response = get_response(request)
               ^^^^^^^^^^^^^^^^^^^^^
  File "/usr/local/lib/python3.12/site-packages/django/core/handlers/base.py", line 197, in _get_response
    response = wrapped_callback(request, *callback_args, **callback_kwargs)
               ^^^^^^^^^^^^^^^^^^^^^^^^^^^^^^^^^^^^^^^^^^^^^^^^^^^^^^^^^^^^
  File "/usr/local/lib/python3.12/site-packages/django/views/decorators/csrf.py", line 65, in _view_wrapper
    return view_func(request, *args, **kwargs)
           ^^^^^^^^^^^^^^^^^^^^^^^^^^^^^^^^^^^
  File "/usr/local/lib/python3.12/site-packages/django/views/generic/base.py", line 105, in view
    return self.dispatch(request, *args, **kwargs)
           ^^^^^^^^^^^^^^^^^^^^^^^^^^^^^^^^^^^^^^^
  File "/usr/local/lib/python3.12/site-packages/rest_framework/views.py", line 515, in dispatch
    response = self.handle_exception(exc)
               ^^^^^^^^^^^^^^^^^^^^^^^^^^
  File "/usr/local/lib/python3.12/site-packages/rest_framework/views.py", line 475, in handle_exception
    self.raise_uncaught_exception(exc)
  File "/usr/local/lib/python3.12/site-packages/rest_framework/views.py", line 486, in raise_uncaught_exception
    raise exc
  File "/usr/local/lib/python3.12/site-packages/rest_framework/views.py", line 503, in dispatch
    self.initial(request, *args, **kwargs)
  File "/usr/local/lib/python3.12/site-packages/rest_framework/views.py", line 420, in initial
    self.perform_authentication(request)
  File "/usr/local/lib/python3.12/site-packages/rest_framework/views.py", line 330, in perform_authentication
    request.user
  File "/usr/local/lib/python3.12/site-packages/rest_framework/request.py", line 232, in user
    self._authenticate()
  File "/usr/local/lib/python3.12/site-packages/rest_framework/request.py", line 385, in _authenticate
    user_auth_tuple = authenticator.authenticate(self)
                      ^^^^^^^^^^^^^^^^^^^^^^^^^^^^^^^^
  File "/usr/local/lib/python3.12/site-packages/rest_framework/authentication.py", line 127, in authenticate
    if not user or not user.is_active:
           ^^^^
  File "/usr/local/lib/python3.12/site-packages/django/utils/functional.py", line 251, in inner
    self._setup()
  File "/usr/local/lib/python3.12/site-packages/django/utils/functional.py", line 404, in _setup
    self._wrapped = self._setupfunc()
                    ^^^^^^^^^^^^^^^^^
  File "/usr/local/lib/python3.12/site-packages/django/contrib/auth/middleware.py", line 40, in <lambda>
    request.user = SimpleLazyObject(lambda: get_user(request))
                                            ^^^^^^^^^^^^^^^^^
  File "/usr/local/lib/python3.12/site-packages/django/contrib/auth/middleware.py", line 20, in get_user
    request._cached_user = auth.get_user(request)
                           ^^^^^^^^^^^^^^^^^^^^^^
  File "/usr/local/lib/python3.12/site-packages/django/contrib/auth/__init__.py", line 304, in get_user
    user_id = _get_user_session_key(request)
              ^^^^^^^^^^^^^^^^^^^^^^^^^^^^^^
  File "/usr/local/lib/python3.12/site-packages/django/contrib/auth/__init__.py", line 95, in _get_user_session_key
    return get_user_model()._meta.pk.to_python(request.session[SESSION_KEY])
                                               ~~~~~~~~~~~~~~~^^^^^^^^^^^^^
  File "/usr/local/lib/python3.12/site-packages/django/contrib/sessions/backends/base.py", line 55, in __getitem__
    return self._session[key]
           ^^^^^^^^^^^^^
  File "/usr/local/lib/python3.12/site-packages/django/contrib/sessions/backends/base.py", line 249, in _get_session
    self._session_cache = self.load()
                          ^^^^^^^^^^^
  File "/usr/local/lib/python3.12/site-packages/django/contrib/sessions/backends/db.py", line 55, in load
    s = self._get_session_from_db()
        ^^^^^^^^^^^^^^^^^^^^^^^^^^^
  File "/usr/local/lib/python3.12/site-packages/django/contrib/sessions/backends/db.py", line 34, in _get_session_from_db
    return self.model.objects.get(
           ^^^^^^^^^^^^^^^^^^^^^^^
  File "/usr/local/lib/python3.12/site-packages/django/db/models/manager.py", line 87, in manager_method
    return getattr(self.get_queryset(), name)(*args, **kwargs)
           ^^^^^^^^^^^^^^^^^^^^^^^^^^^^^^^^^^^^^^^^^^^^^^^^^^^
  File "/usr/local/lib/python3.12/site-packages/django/db/models/query.py", line 629, in get
    num = len(clone)
          ^^^^^^^^^^
  File "/usr/local/lib/python3.12/site-packages/django/db/models/query.py", line 366, in __len__
    self._fetch_all()
  File "/usr/local/lib/python3.12/site-packages/django/db/models/query.py", line 1949, in _fetch_all
    self._result_cache = list(self._iterable_class(self))
                         ^^^^^^^^^^^^^^^^^^^^^^^^^^^^^^^^
  File "/usr/local/lib/python3.12/site-packages/django/db/models/query.py", line 91, in __iter__
    results = compiler.execute_sql(
              ^^^^^^^^^^^^^^^^^^^^^
  File "/usr/local/lib/python3.12/site-packages/django/db/models/sql/compiler.py", line 1623, in execute_sql
    cursor.execute(sql, params)
  File "/usr/local/lib/python3.12/site-packages/django/db/backends/utils.py", line 122, in execute
    return super().execute(sql, params)
           ^^^^^^^^^^^^^^^^^^^^^^^^^^^^
  File "/usr/local/lib/python3.12/site-packages/django/db/backends/utils.py", line 79, in execute
    return self._execute_with_wrappers(
           ^^^^^^^^^^^^^^^^^^^^^^^^^^^^
  File "/usr/local/lib/python3.12/site-packages/django/db/backends/utils.py", line 92, in _execute_with_wrappers
    return executor(sql, params, many, context)
           ^^^^^^^^^^^^^^^^^^^^^^^^^^^^^^^^^^^^
  File "/usr/local/lib/python3.12/site-packages/django/db/backends/utils.py", line 100, in _execute
    with self.db.wrap_database_errors:
         ^^^^^^^^^^^^^^^^^^^^^^^^^^^^
  File "/usr/local/lib/python3.12/site-packages/django/db/utils.py", line 91, in __exit__
    raise dj_exc_value.with_traceback(traceback) from exc_value
  File "/usr/local/lib/python3.12/site-packages/django/db/backends/utils.py", line 105, in _execute
    return self.cursor.execute(sql, params)
           ^^^^^^^^^^^^^^^^^^^^^^^^^^^^^^^^
django.db.utils.ProgrammingError: relation "django_session" does not exist
LINE 1: ...ession_data", "django_session"."expire_date" FROM "django_se...
                                                             ^

[2025-09-22 14:42:32,668] ERROR django.server:213 — "GET / HTTP/1.1" 500 211995
[2025-09-22 14:43:06,194] INFO django.utils.autoreload:667 — Watching for file changes with StatReloader
[2025-09-22 14:43:06,821] ERROR django.request:253 — Internal Server Error: /
Traceback (most recent call last):
  File "/usr/local/lib/python3.12/site-packages/django/contrib/sessions/backends/base.py", line 244, in _get_session
    return self._session_cache
           ^^^^^^^^^^^^^^^^^^^
AttributeError: 'SessionStore' object has no attribute '_session_cache'

During handling of the above exception, another exception occurred:

Traceback (most recent call last):
  File "/usr/local/lib/python3.12/site-packages/django/db/backends/utils.py", line 105, in _execute
    return self.cursor.execute(sql, params)
           ^^^^^^^^^^^^^^^^^^^^^^^^^^^^^^^^
psycopg2.errors.UndefinedTable: relation "django_session" does not exist
LINE 1: ...ession_data", "django_session"."expire_date" FROM "django_se...
                                                             ^


The above exception was the direct cause of the following exception:

Traceback (most recent call last):
  File "/usr/local/lib/python3.12/site-packages/django/core/handlers/exception.py", line 55, in inner
    response = get_response(request)
               ^^^^^^^^^^^^^^^^^^^^^
  File "/usr/local/lib/python3.12/site-packages/django/core/handlers/base.py", line 197, in _get_response
    response = wrapped_callback(request, *callback_args, **callback_kwargs)
               ^^^^^^^^^^^^^^^^^^^^^^^^^^^^^^^^^^^^^^^^^^^^^^^^^^^^^^^^^^^^
  File "/usr/local/lib/python3.12/site-packages/django/views/decorators/csrf.py", line 65, in _view_wrapper
    return view_func(request, *args, **kwargs)
           ^^^^^^^^^^^^^^^^^^^^^^^^^^^^^^^^^^^
  File "/usr/local/lib/python3.12/site-packages/django/views/generic/base.py", line 105, in view
    return self.dispatch(request, *args, **kwargs)
           ^^^^^^^^^^^^^^^^^^^^^^^^^^^^^^^^^^^^^^^
  File "/usr/local/lib/python3.12/site-packages/rest_framework/views.py", line 515, in dispatch
    response = self.handle_exception(exc)
               ^^^^^^^^^^^^^^^^^^^^^^^^^^
  File "/usr/local/lib/python3.12/site-packages/rest_framework/views.py", line 475, in handle_exception
    self.raise_uncaught_exception(exc)
  File "/usr/local/lib/python3.12/site-packages/rest_framework/views.py", line 486, in raise_uncaught_exception
    raise exc
  File "/usr/local/lib/python3.12/site-packages/rest_framework/views.py", line 503, in dispatch
    self.initial(request, *args, **kwargs)
  File "/usr/local/lib/python3.12/site-packages/rest_framework/views.py", line 420, in initial
    self.perform_authentication(request)
  File "/usr/local/lib/python3.12/site-packages/rest_framework/views.py", line 330, in perform_authentication
    request.user
  File "/usr/local/lib/python3.12/site-packages/rest_framework/request.py", line 232, in user
    self._authenticate()
  File "/usr/local/lib/python3.12/site-packages/rest_framework/request.py", line 385, in _authenticate
    user_auth_tuple = authenticator.authenticate(self)
                      ^^^^^^^^^^^^^^^^^^^^^^^^^^^^^^^^
  File "/usr/local/lib/python3.12/site-packages/rest_framework/authentication.py", line 127, in authenticate
    if not user or not user.is_active:
           ^^^^
  File "/usr/local/lib/python3.12/site-packages/django/utils/functional.py", line 251, in inner
    self._setup()
  File "/usr/local/lib/python3.12/site-packages/django/utils/functional.py", line 404, in _setup
    self._wrapped = self._setupfunc()
                    ^^^^^^^^^^^^^^^^^
  File "/usr/local/lib/python3.12/site-packages/django/contrib/auth/middleware.py", line 40, in <lambda>
    request.user = SimpleLazyObject(lambda: get_user(request))
                                            ^^^^^^^^^^^^^^^^^
  File "/usr/local/lib/python3.12/site-packages/django/contrib/auth/middleware.py", line 20, in get_user
    request._cached_user = auth.get_user(request)
                           ^^^^^^^^^^^^^^^^^^^^^^
  File "/usr/local/lib/python3.12/site-packages/django/contrib/auth/__init__.py", line 304, in get_user
    user_id = _get_user_session_key(request)
              ^^^^^^^^^^^^^^^^^^^^^^^^^^^^^^
  File "/usr/local/lib/python3.12/site-packages/django/contrib/auth/__init__.py", line 95, in _get_user_session_key
    return get_user_model()._meta.pk.to_python(request.session[SESSION_KEY])
                                               ~~~~~~~~~~~~~~~^^^^^^^^^^^^^
  File "/usr/local/lib/python3.12/site-packages/django/contrib/sessions/backends/base.py", line 55, in __getitem__
    return self._session[key]
           ^^^^^^^^^^^^^
  File "/usr/local/lib/python3.12/site-packages/django/contrib/sessions/backends/base.py", line 249, in _get_session
    self._session_cache = self.load()
                          ^^^^^^^^^^^
  File "/usr/local/lib/python3.12/site-packages/django/contrib/sessions/backends/db.py", line 55, in load
    s = self._get_session_from_db()
        ^^^^^^^^^^^^^^^^^^^^^^^^^^^
  File "/usr/local/lib/python3.12/site-packages/django/contrib/sessions/backends/db.py", line 34, in _get_session_from_db
    return self.model.objects.get(
           ^^^^^^^^^^^^^^^^^^^^^^^
  File "/usr/local/lib/python3.12/site-packages/django/db/models/manager.py", line 87, in manager_method
    return getattr(self.get_queryset(), name)(*args, **kwargs)
           ^^^^^^^^^^^^^^^^^^^^^^^^^^^^^^^^^^^^^^^^^^^^^^^^^^^
  File "/usr/local/lib/python3.12/site-packages/django/db/models/query.py", line 629, in get
    num = len(clone)
          ^^^^^^^^^^
  File "/usr/local/lib/python3.12/site-packages/django/db/models/query.py", line 366, in __len__
    self._fetch_all()
  File "/usr/local/lib/python3.12/site-packages/django/db/models/query.py", line 1949, in _fetch_all
    self._result_cache = list(self._iterable_class(self))
                         ^^^^^^^^^^^^^^^^^^^^^^^^^^^^^^^^
  File "/usr/local/lib/python3.12/site-packages/django/db/models/query.py", line 91, in __iter__
    results = compiler.execute_sql(
              ^^^^^^^^^^^^^^^^^^^^^
  File "/usr/local/lib/python3.12/site-packages/django/db/models/sql/compiler.py", line 1623, in execute_sql
    cursor.execute(sql, params)
  File "/usr/local/lib/python3.12/site-packages/django/db/backends/utils.py", line 122, in execute
    return super().execute(sql, params)
           ^^^^^^^^^^^^^^^^^^^^^^^^^^^^
  File "/usr/local/lib/python3.12/site-packages/django/db/backends/utils.py", line 79, in execute
    return self._execute_with_wrappers(
           ^^^^^^^^^^^^^^^^^^^^^^^^^^^^
  File "/usr/local/lib/python3.12/site-packages/django/db/backends/utils.py", line 92, in _execute_with_wrappers
    return executor(sql, params, many, context)
           ^^^^^^^^^^^^^^^^^^^^^^^^^^^^^^^^^^^^
  File "/usr/local/lib/python3.12/site-packages/django/db/backends/utils.py", line 100, in _execute
    with self.db.wrap_database_errors:
         ^^^^^^^^^^^^^^^^^^^^^^^^^^^^
  File "/usr/local/lib/python3.12/site-packages/django/db/utils.py", line 91, in __exit__
    raise dj_exc_value.with_traceback(traceback) from exc_value
  File "/usr/local/lib/python3.12/site-packages/django/db/backends/utils.py", line 105, in _execute
    return self.cursor.execute(sql, params)
           ^^^^^^^^^^^^^^^^^^^^^^^^^^^^^^^^
django.db.utils.ProgrammingError: relation "django_session" does not exist
LINE 1: ...ession_data", "django_session"."expire_date" FROM "django_se...
                                                             ^

[2025-09-22 14:43:06,827] ERROR django.server:213 — "GET / HTTP/1.1" 500 211986
[2025-09-22 14:43:54,794] INFO django.server:213 — "GET / HTTP/1.1" 200 5189
[2025-09-22 14:43:54,856] INFO django.server:213 — "GET /products/api HTTP/1.1" 301 0
[2025-09-22 14:43:54,856] INFO django.server:213 — "GET /user/api/check-auth/ HTTP/1.1" 200 23
[2025-09-22 14:43:55,162] INFO django.server:213 — "GET /products/api/ HTTP/1.1" 200 85
[2025-09-22 14:43:55,754] INFO django.server:213 — "GET / HTTP/1.1" 200 5189
[2025-09-22 14:44:07,109] INFO django.server:213 — "GET /user/api/check-auth/ HTTP/1.1" 200 23
[2025-09-22 14:44:07,109] INFO django.server:213 — "GET /products/api HTTP/1.1" 301 0
[2025-09-22 14:44:07,177] INFO django.server:213 — "GET /products/api/ HTTP/1.1" 200 85
[2025-09-22 14:44:12,684] INFO django.server:213 — "GET /admin HTTP/1.1" 301 0
[2025-09-22 14:44:12,717] INFO django.server:213 — "GET /admin/ HTTP/1.1" 302 0
[2025-09-22 14:44:12,749] INFO django.server:213 — "GET /admin/login/?next=/admin/ HTTP/1.1" 200 4173
[2025-09-22 14:44:16,249] INFO django.server:213 — "POST /admin/login/?next=/admin/ HTTP/1.1" 200 4339
[2025-09-22 14:44:22,924] INFO django.server:213 — "POST /admin/login/?next=/admin/ HTTP/1.1" 200 4339
[2025-09-22 14:44:26,045] INFO django.server:213 — "POST /admin/login/?next=/admin/ HTTP/1.1" 200 4339
[2025-09-22 14:44:31,627] INFO django.server:213 — "GET / HTTP/1.1" 200 5189
[2025-09-22 14:45:32,260] INFO django.utils.autoreload:265 — /app/users/models.py changed, reloading.
[2025-09-22 14:45:32,782] INFO django.utils.autoreload:667 — Watching for file changes with StatReloader
[2025-09-22 14:45:58,422] INFO django.server:213 — "GET /admin HTTP/1.1" 301 0
[2025-09-22 14:45:58,448] INFO django.server:213 — "GET /admin/ HTTP/1.1" 302 0
[2025-09-22 14:45:58,479] INFO django.server:213 — "GET /admin/login/?next=/admin/ HTTP/1.1" 200 4173
[2025-09-22 14:46:02,565] INFO django.server:213 — "POST /admin/login/?next=/admin/ HTTP/1.1" 302 0
[2025-09-22 14:46:02,590] INFO django.server:213 — "GET /admin/ HTTP/1.1" 200 13262
[2025-09-22 14:46:02,787] INFO django.server:213 — "GET /static/admin/img/icon-addlink.svg HTTP/1.1" 200 331
[2025-09-22 14:46:02,788] INFO django.server:213 — "GET /static/admin/img/icon-changelink.svg HTTP/1.1" 200 380
[2025-09-22 14:46:04,480] INFO django.server:213 — "GET /admin/users/myuser/ HTTP/1.1" 200 15656
[2025-09-22 14:46:04,544] INFO django.server:213 — "GET /admin/jsi18n/ HTTP/1.1" 200 3342
[2025-09-22 14:46:04,548] INFO django.server:213 — "GET /static/admin/img/icon-yes.svg HTTP/1.1" 200 436
[2025-09-22 14:46:04,548] INFO django.server:213 — "GET /static/admin/img/icon-no.svg HTTP/1.1" 200 560
[2025-09-22 14:46:04,680] INFO django.server:213 — "GET /static/admin/img/tooltag-add.svg HTTP/1.1" 200 331
[2025-09-22 14:46:15,729] INFO django.server:213 — "GET /admin/products/product/ HTTP/1.1" 200 13848
[2025-09-22 14:46:15,800] INFO django.server:213 — "GET /admin/jsi18n/ HTTP/1.1" 200 3342
[2025-09-22 14:46:15,950] INFO django.server:213 — "GET /static/admin/img/icon-viewlink.svg HTTP/1.1" 200 581
[2025-09-22 14:46:18,397] INFO django.server:213 — "GET /admin/products/product/add/ HTTP/1.1" 200 23643
[2025-09-22 14:46:18,447] INFO django.server:213 — "GET /static/admin/css/forms.css HTTP/1.1" 200 8525
[2025-09-22 14:46:18,450] INFO django.server:213 — "GET /static/admin/js/change_form.js HTTP/1.1" 200 606
[2025-09-22 14:46:18,452] INFO django.server:213 — "GET /static/admin/js/prepopulate_init.js HTTP/1.1" 200 586
[2025-09-22 14:46:18,456] INFO django.server:213 — "GET /admin/jsi18n/ HTTP/1.1" 200 3342
[2025-09-22 14:46:18,612] INFO django.server:213 — "GET /static/admin/css/widgets.css HTTP/1.1" 200 11991
[2025-09-22 14:46:24,418] INFO django.server:213 — "GET /admin/products/category/add/?_to_field=id&_popup=1 HTTP/1.1" 200 4389
[2025-09-22 14:46:24,523] INFO django.server:213 — "GET /admin/jsi18n/ HTTP/1.1" 200 3342
[2025-09-22 14:46:26,505] INFO django.server:213 — "POST /admin/products/category/add/?_to_field=id&_popup=1 HTTP/1.1" 200 322
[2025-09-22 14:46:26,530] INFO django.server:213 — "GET /static/admin/js/popup_response.js HTTP/1.1" 200 532
[2025-09-22 14:46:28,285] INFO django.server:213 — "GET /admin/products/subcategory/add/?_to_field=id&_popup=1 HTTP/1.1" 200 6139
[2025-09-22 14:46:28,356] INFO django.server:213 — "GET /admin/jsi18n/ HTTP/1.1" 200 3342
[2025-09-22 14:46:32,543] INFO django.server:213 — "POST /admin/products/subcategory/add/?_to_field=id&_popup=1 HTTP/1.1" 200 323
[2025-09-22 14:47:06,580] INFO django.server:213 — "POST /admin/products/product/add/ HTTP/1.1" 302 0
[2025-09-22 14:47:06,626] INFO django.server:213 — "GET /admin/products/product/1/change/ HTTP/1.1" 200 24325
[2025-09-22 14:47:06,690] INFO django.server:213 — "GET /admin/jsi18n/ HTTP/1.1" 200 3342
[2025-09-22 14:47:09,774] INFO django.server:213 — "GET /products/api HTTP/1.1" 301 0
[2025-09-22 14:47:09,782] INFO django.server:213 — "GET /user/api/check-auth/ HTTP/1.1" 200 39
[2025-09-22 14:47:09,859] INFO django.server:213 — "GET /products/api/ HTTP/1.1" 200 510
[2025-09-22 14:47:09,884] INFO django.server:213 — "GET /media/catalog/photo_2025-06-17_19-04-21.jpg HTTP/1.1" 200 51047
[2025-09-22 14:47:14,639] INFO django.server:213 — "GET /products/api HTTP/1.1" 301 0
[2025-09-22 14:47:14,645] INFO django.server:213 — "GET /user/api/check-auth/ HTTP/1.1" 200 39
[2025-09-22 14:47:14,667] INFO django.server:213 — "GET /products/api/ HTTP/1.1" 200 510
[2025-09-22 14:47:14,705] INFO django.server:213 — "GET /media/catalog/photo_2025-06-17_19-04-21.jpg HTTP/1.1" 304 0
[2025-09-22 14:47:15,667] INFO django.server:213 — "GET /products/1/ HTTP/1.1" 200 342
[2025-09-22 14:47:20,037] INFO django.server:213 — "GET /products/api HTTP/1.1" 301 0
[2025-09-22 14:47:20,065] INFO django.server:213 — "GET /products/api/ HTTP/1.1" 200 510
=======
[2025-09-22 14:31:57,266] INFO django.utils.autoreload:667 — Watching for file changes with StatReloader
[2025-09-22 14:39:26,064] INFO django.utils.autoreload:667 — Watching for file changes with StatReloader
[2025-09-22 14:40:45,532] INFO django.server:213 — "GET /products/api HTTP/1.1" 301 0
[2025-09-22 14:40:45,539] INFO django.server:213 — "GET /user/api/check-auth/ HTTP/1.1" 200 23
[2025-09-22 14:40:45,562] ERROR django.request:253 — Internal Server Error: /products/api/
[2025-09-22 14:40:45,562] ERROR django.server:213 — "GET /products/api/ HTTP/1.1" 500 317
[2025-09-22 14:41:52,770] INFO django.server:213 — "GET /admin HTTP/1.1" 301 0
[2025-09-22 14:41:52,800] INFO django.server:213 — "GET /admin/ HTTP/1.1" 302 0
[2025-09-22 14:41:52,841] INFO django.server:213 — "GET /admin/login/?next=/admin/ HTTP/1.1" 200 4173
[2025-09-22 14:41:52,872] INFO django.server:213 — "GET /static/admin/css/nav_sidebar.css HTTP/1.1" 200 2810
[2025-09-22 14:41:52,872] INFO django.server:213 — "GET /static/admin/css/login.css HTTP/1.1" 200 951
[2025-09-22 14:41:52,873] INFO django.server:213 — "GET /static/admin/css/dark_mode.css HTTP/1.1" 200 2808
[2025-09-22 14:41:52,873] INFO django.server:213 — "GET /static/admin/js/theme.js HTTP/1.1" 200 1653
[2025-09-22 14:41:52,874] INFO django.server:213 — "GET /static/admin/css/responsive.css HTTP/1.1" 200 16565
[2025-09-22 14:41:52,874] INFO django.server:213 — "GET /static/admin/css/base.css HTTP/1.1" 200 22120
[2025-09-22 14:41:52,878] INFO django.server:213 — "GET /static/admin/js/nav_sidebar.js HTTP/1.1" 200 3063
[2025-09-22 14:41:52,938] WARNING django.request:253 — Not Found: /favicon.ico
[2025-09-22 14:41:52,939] WARNING django.server:213 — "GET /favicon.ico HTTP/1.1" 404 3299
[2025-09-22 14:41:55,318] INFO django.server:213 — "POST /admin/login/?next=/admin/ HTTP/1.1" 200 4337
[2025-09-22 14:41:59,241] INFO django.server:213 — "POST /admin/login/?next=/admin/ HTTP/1.1" 200 4337
[2025-09-22 14:42:17,465] INFO django.server:213 — "GET /user/api/check-auth/ HTTP/1.1" 200 23
[2025-09-22 14:42:17,470] ERROR django.request:253 — Internal Server Error: /products/api/
[2025-09-22 14:42:17,472] ERROR django.server:213 — "GET /products/api/ HTTP/1.1" 500 317
[2025-09-22 14:54:06,173] INFO django.utils.autoreload:265 — /app/users/models.py changed, reloading.
[2025-09-22 14:54:06,621] INFO django.utils.autoreload:667 — Watching for file changes with StatReloader
[2025-09-22 14:54:09,213] INFO django.utils.autoreload:265 — /app/cart/views.py changed, reloading.
[2025-09-22 14:54:09,588] INFO django.utils.autoreload:667 — Watching for file changes with StatReloader
[2025-09-22 14:54:11,087] INFO django.utils.autoreload:265 — /app/shop/views.py changed, reloading.
[2025-09-22 14:54:11,470] INFO django.utils.autoreload:667 — Watching for file changes with StatReloader
[2025-09-22 14:54:53,853] INFO django.utils.autoreload:265 — /app/users/models.py changed, reloading.
[2025-09-22 14:54:54,244] INFO django.utils.autoreload:667 — Watching for file changes with StatReloader
[2025-09-22 15:03:57,929] INFO django.utils.autoreload:265 — /app/orders/models.py changed, reloading.
[2025-09-22 15:03:58,296] INFO django.utils.autoreload:667 — Watching for file changes with StatReloader
[2025-09-22 15:04:06,598] INFO django.utils.autoreload:265 — /app/orders/models.py changed, reloading.
[2025-09-22 15:04:06,953] INFO django.utils.autoreload:667 — Watching for file changes with StatReloader
[2025-09-22 15:05:49,625] INFO django.utils.autoreload:265 — /app/orders/models.py changed, reloading.
[2025-09-22 15:05:49,990] INFO django.utils.autoreload:667 — Watching for file changes with StatReloader
[2025-09-22 15:06:58,657] INFO django.utils.autoreload:265 — /app/orders/models.py changed, reloading.
[2025-09-22 15:06:59,020] INFO django.utils.autoreload:667 — Watching for file changes with StatReloader
[2025-09-22 15:07:04,292] INFO django.utils.autoreload:265 — /app/orders/utils.py changed, reloading.
[2025-09-22 15:07:04,637] INFO django.utils.autoreload:667 — Watching for file changes with StatReloader
>>>>>>> 4981badf424ed1e9b6a866f415927a0f70db6850
[2025-09-22 15:52:09,938] INFO django.utils.autoreload:667 — Watching for file changes with StatReloader
[2025-09-22 15:55:31,662] INFO django.utils.autoreload:265 — /app/cart/views.py changed, reloading.
[2025-09-22 15:55:32,036] INFO django.utils.autoreload:667 — Watching for file changes with StatReloader
[2025-09-22 15:56:48,387] INFO django.utils.autoreload:265 — /app/cart/views.py changed, reloading.
[2025-09-22 15:56:48,770] INFO django.utils.autoreload:667 — Watching for file changes with StatReloader
[2025-09-22 15:57:12,301] INFO django.utils.autoreload:265 — /app/cart/views.py changed, reloading.
[2025-09-22 15:57:12,699] INFO django.utils.autoreload:667 — Watching for file changes with StatReloader
[2025-09-22 15:59:19,007] INFO django.utils.autoreload:265 — /app/cart/admin.py changed, reloading.
[2025-09-22 15:59:19,404] INFO django.utils.autoreload:667 — Watching for file changes with StatReloader
[2025-09-22 15:59:54,590] INFO django.utils.autoreload:667 — Watching for file changes with StatReloader
[2025-09-22 16:01:19,963] INFO django.utils.autoreload:667 — Watching for file changes with StatReloader
[2025-09-22 16:02:58,590] INFO django.utils.autoreload:265 — /app/cart/admin.py changed, reloading.
[2025-09-22 16:02:58,986] INFO django.utils.autoreload:667 — Watching for file changes with StatReloader
[2025-09-22 16:03:11,240] INFO django.utils.autoreload:667 — Watching for file changes with StatReloader
[2025-09-22 16:03:45,709] INFO django.utils.autoreload:265 — /app/cart/admin.py changed, reloading.
[2025-09-22 16:03:46,108] INFO django.utils.autoreload:667 — Watching for file changes with StatReloader
[2025-09-22 16:18:47,476] INFO django.utils.autoreload:667 — Watching for file changes with StatReloader
[2025-09-22 16:20:23,247] INFO django.utils.autoreload:667 — Watching for file changes with StatReloader
[2025-09-22 16:21:43,784] INFO django.utils.autoreload:667 — Watching for file changes with StatReloader
[2025-09-22 16:21:53,455] INFO django.server:213 — "GET /user/api/check-auth/ HTTP/1.1" 200 37
[2025-09-22 16:21:53,456] INFO django.server:213 — "GET /products/api/ HTTP/1.1" 200 960
[2025-09-22 16:21:55,052] INFO django.server:213 — "GET /products/1/ HTTP/1.1" 200 782
[2025-09-22 16:21:57,886] INFO django.server:213 — "GET /cart/ HTTP/1.1" 200 5258
[2025-09-22 16:21:58,965] INFO django.server:213 — "GET /cart/ HTTP/1.1" 200 5258
[2025-09-22 16:21:59,145] INFO django.server:213 — "GET /cart/ HTTP/1.1" 200 5258
[2025-09-22 16:22:01,146] INFO django.server:213 — "OPTIONS /cart/api/add/ HTTP/1.1" 200 0
[2025-09-22 16:22:01,158] WARNING django.request:253 — Not Found: /cart/api/add/
[2025-09-22 16:22:01,159] WARNING django.server:213 — "POST /cart/api/add/ HTTP/1.1" 404 4738
[2025-09-22 16:22:34,250] WARNING django.request:253 — Not Found: /cart/api/add/
[2025-09-22 16:22:34,251] WARNING django.server:213 — "POST /cart/api/add/ HTTP/1.1" 404 4738
[2025-09-22 16:23:03,617] INFO django.server:213 — "GET /products/1/ HTTP/1.1" 200 782
[2025-09-22 16:23:03,619] INFO django.server:213 — "GET /user/api/check-auth/ HTTP/1.1" 200 37
[2025-09-22 16:23:05,706] ERROR django.request:253 — Internal Server Error: /cart/api/add/1/
Traceback (most recent call last):
  File "/usr/local/lib/python3.12/site-packages/django/core/handlers/exception.py", line 55, in inner
    response = get_response(request)
               ^^^^^^^^^^^^^^^^^^^^^
  File "/usr/local/lib/python3.12/site-packages/django/core/handlers/base.py", line 197, in _get_response
    response = wrapped_callback(request, *callback_args, **callback_kwargs)
               ^^^^^^^^^^^^^^^^^^^^^^^^^^^^^^^^^^^^^^^^^^^^^^^^^^^^^^^^^^^^
  File "/usr/local/lib/python3.12/site-packages/django/views/decorators/csrf.py", line 65, in _view_wrapper
    return view_func(request, *args, **kwargs)
           ^^^^^^^^^^^^^^^^^^^^^^^^^^^^^^^^^^^
  File "/usr/local/lib/python3.12/site-packages/django/views/generic/base.py", line 105, in view
    return self.dispatch(request, *args, **kwargs)
           ^^^^^^^^^^^^^^^^^^^^^^^^^^^^^^^^^^^^^^^
  File "/usr/local/lib/python3.12/site-packages/rest_framework/views.py", line 515, in dispatch
    response = self.handle_exception(exc)
               ^^^^^^^^^^^^^^^^^^^^^^^^^^
  File "/usr/local/lib/python3.12/site-packages/rest_framework/views.py", line 475, in handle_exception
    self.raise_uncaught_exception(exc)
  File "/usr/local/lib/python3.12/site-packages/rest_framework/views.py", line 486, in raise_uncaught_exception
    raise exc
  File "/usr/local/lib/python3.12/site-packages/rest_framework/views.py", line 512, in dispatch
    response = handler(request, *args, **kwargs)
               ^^^^^^^^^^^^^^^^^^^^^^^^^^^^^^^^^
  File "/usr/local/lib/python3.12/site-packages/rest_framework/decorators.py", line 50, in handler
    return func(*args, **kwargs)
           ^^^^^^^^^^^^^^^^^^^^^
TypeError: cart_items() got an unexpected keyword argument 'product_id'
[2025-09-22 16:23:05,709] ERROR django.server:213 — "POST /cart/api/add/1/ HTTP/1.1" 500 86427
[2025-09-22 16:23:21,588] INFO django.server:213 — "GET /products/1/ HTTP/1.1" 200 782
[2025-09-22 16:23:21,592] INFO django.server:213 — "GET /user/api/check-auth/ HTTP/1.1" 200 37
[2025-09-22 16:23:23,466] WARNING django.request:253 — Not Found: /cart/api/add/
[2025-09-22 16:23:23,467] WARNING django.server:213 — "POST /cart/api/add/ HTTP/1.1" 404 4738
[2025-09-22 16:24:57,135] INFO django.server:213 — "GET /products/1/ HTTP/1.1" 200 782
[2025-09-22 16:24:57,139] INFO django.server:213 — "GET /user/api/check-auth/ HTTP/1.1" 200 37
[2025-09-22 16:24:59,303] WARNING django.request:253 — Not Found: /cart/api/add/
[2025-09-22 16:24:59,304] WARNING django.server:213 — "POST /cart/api/add/ HTTP/1.1" 404 4738
[2025-09-22 16:27:39,756] INFO django.utils.autoreload:265 — /app/cart/urls.py changed, reloading.
[2025-09-22 16:27:40,684] INFO django.utils.autoreload:667 — Watching for file changes with StatReloader
[2025-09-22 16:27:50,410] INFO django.utils.autoreload:667 — Watching for file changes with StatReloader
[2025-09-22 16:27:52,545] INFO django.server:213 — "GET /user/api/check-auth/ HTTP/1.1" 200 37
[2025-09-22 16:27:52,546] INFO django.server:213 — "GET /products/1/ HTTP/1.1" 200 782
[2025-09-22 16:27:53,954] ERROR django.request:253 — Internal Server Error: /cart/api/add/
[2025-09-22 16:27:53,956] ERROR django.server:213 — "POST /cart/api/add/ HTTP/1.1" 500 72
[2025-09-22 16:32:17,994] INFO django.utils.autoreload:265 — /app/cart/views.py changed, reloading.
[2025-09-22 16:32:23,947] INFO django.utils.autoreload:667 — Watching for file changes with StatReloader
[2025-09-22 16:32:26,773] INFO django.server:213 — "GET /products/1/ HTTP/1.1" 200 782
[2025-09-22 16:32:26,790] INFO django.server:213 — "GET /user/api/check-auth/ HTTP/1.1" 200 37
[2025-09-22 16:32:29,235] INFO django.server:213 — "GET /cart/ HTTP/1.1" 200 5258
[2025-09-22 16:32:31,078] INFO django.server:213 — "GET /cart/ HTTP/1.1" 200 55
[2025-09-22 16:32:35,721] INFO django.server:213 — "GET /cart/ HTTP/1.1" 200 5258
[2025-09-22 16:32:36,596] INFO django.server:213 — "GET /cart/ HTTP/1.1" 200 5258
[2025-09-22 16:32:42,272] INFO django.server:213 — "GET /user/api/check-auth/ HTTP/1.1" 200 37
[2025-09-22 16:32:42,282] INFO django.server:213 — "GET /products/api/ HTTP/1.1" 200 960
[2025-09-22 16:32:43,576] INFO django.server:213 — "GET /products/1/ HTTP/1.1" 200 782
[2025-09-22 16:32:45,051] INFO django.server:213 — "POST /cart/api/add/ HTTP/1.1" 200 245
[2025-09-22 16:32:47,641] INFO django.server:213 — "GET /cart/ HTTP/1.1" 200 5258
[2025-09-22 16:32:48,563] INFO django.server:213 — "GET /cart/ HTTP/1.1" 200 5258
[2025-09-22 16:32:51,354] WARNING django.request:253 — Not Found: /cart/api/add/1/
[2025-09-22 16:32:51,355] WARNING django.server:213 — "GET /cart/api/add/1/ HTTP/1.1" 404 4720
[2025-09-22 16:32:55,810] INFO django.server:213 — "GET /cart/api/add/ HTTP/1.1" 200 7092
[2025-09-22 16:33:06,957] INFO django.server:213 — "GET /admin/cart/cartitem/ HTTP/1.1" 200 15747
[2025-09-22 16:33:07,019] INFO django.server:213 — "GET /admin/jsi18n/ HTTP/1.1" 200 3342
[2025-09-22 16:33:09,222] INFO django.server:213 — "GET /admin/cart/carts/ HTTP/1.1" 200 16225
[2025-09-22 16:33:09,299] INFO django.server:213 — "GET /admin/jsi18n/ HTTP/1.1" 200 3342
[2025-09-22 16:33:10,774] INFO django.server:213 — "GET /admin/cart/carts/ HTTP/1.1" 200 16225
[2025-09-22 16:33:10,835] INFO django.server:213 — "GET /admin/jsi18n/ HTTP/1.1" 200 3342
[2025-09-22 16:33:13,908] INFO django.server:213 — "POST /cart/api/add/ HTTP/1.1" 200 245
[2025-09-22 16:33:14,272] INFO django.server:213 — "POST /cart/api/add/ HTTP/1.1" 200 245
[2025-09-22 16:33:14,633] INFO django.server:213 — "POST /cart/api/add/ HTTP/1.1" 200 245
[2025-09-22 16:33:17,031] INFO django.server:213 — "GET /admin/cart/carts/ HTTP/1.1" 200 17326
[2025-09-22 16:33:17,087] INFO django.server:213 — "GET /admin/jsi18n/ HTTP/1.1" 200 3342
[2025-09-22 16:33:19,135] INFO django.server:213 — "GET /admin/cart/cartitem/ HTTP/1.1" 200 17280
[2025-09-22 16:33:19,194] INFO django.server:213 — "GET /admin/jsi18n/ HTTP/1.1" 200 3342
[2025-09-22 16:33:32,185] WARNING django.request:253 — Bad Request: /cart/api/add/
[2025-09-22 16:33:32,187] WARNING django.server:213 — "POST /cart/api/add/ HTTP/1.1" 400 7086
[2025-09-22 16:33:44,978] WARNING django.request:253 — Bad Request: /cart/api/add/
[2025-09-22 16:33:44,979] WARNING django.server:213 — "POST /cart/api/add/ HTTP/1.1" 400 7120
[2025-09-22 16:34:20,309] WARNING django.request:253 — Bad Request: /cart/api/add/
[2025-09-22 16:34:20,311] WARNING django.server:213 — "POST /cart/api/add/ HTTP/1.1" 400 7120
[2025-09-22 16:34:35,682] INFO django.utils.autoreload:265 — /app/cart/views.py changed, reloading.
[2025-09-22 16:34:36,658] INFO django.utils.autoreload:667 — Watching for file changes with StatReloader
[2025-09-22 16:34:43,668] WARNING django.request:253 — Bad Request: /cart/api/add/
[2025-09-22 16:34:43,672] WARNING django.server:213 — "POST /cart/api/add/ HTTP/1.1" 400 7120
[2025-09-22 16:36:10,496] INFO django.utils.autoreload:265 — /app/cart/views.py changed, reloading.
[2025-09-22 16:36:11,367] INFO django.utils.autoreload:667 — Watching for file changes with StatReloader
[2025-09-22 16:36:23,586] ERROR django.request:253 — Internal Server Error: /cart/api/add/
[2025-09-22 16:36:23,588] ERROR django.server:213 — "POST /cart/api/add/ HTTP/1.1" 500 7171
[2025-09-22 16:36:40,512] INFO django.server:213 — "GET /cart/ HTTP/1.1" 200 5258
[2025-09-22 16:38:16,054] INFO django.utils.autoreload:265 — /app/cart/views.py changed, reloading.
[2025-09-22 16:38:17,475] INFO django.utils.autoreload:667 — Watching for file changes with StatReloader
[2025-09-22 16:39:14,379] INFO django.utils.autoreload:265 — /app/cart/views.py changed, reloading.
[2025-09-22 16:39:15,269] INFO django.utils.autoreload:667 — Watching for file changes with StatReloader
[2025-09-22 16:39:29,957] INFO django.utils.autoreload:265 — /app/cart/views.py changed, reloading.
[2025-09-22 16:39:30,959] INFO django.utils.autoreload:667 — Watching for file changes with StatReloader
[2025-09-22 16:39:58,685] INFO django.utils.autoreload:667 — Watching for file changes with StatReloader
[2025-09-22 16:40:01,761] INFO django.server:213 — "GET /cart/ HTTP/1.1" 200 5258
[2025-09-22 16:40:02,423] INFO django.server:213 — "GET /cart/ HTTP/1.1" 200 5258
[2025-09-22 16:40:06,560] INFO django.server:213 — "GET /user/api/check-auth/ HTTP/1.1" 200 37
[2025-09-22 16:40:06,561] INFO django.server:213 — "GET /products/1/ HTTP/1.1" 200 782
[2025-09-22 16:40:08,026] INFO django.server:213 — "POST /cart/api/add/ HTTP/1.1" 200 340
[2025-09-22 16:40:11,486] INFO django.server:213 — "GET /cart/ HTTP/1.1" 200 5258
[2025-09-22 16:40:12,285] INFO django.server:213 — "GET /cart/ HTTP/1.1" 200 5258
[2025-09-22 16:40:13,501] INFO django.server:213 — "GET /cart/ HTTP/1.1" 200 5258
[2025-09-22 16:40:15,281] WARNING django.request:253 — Method Not Allowed: /cart/api/add/
[2025-09-22 16:40:15,283] WARNING django.server:213 — "GET /cart/api/add/ HTTP/1.1" 405 5791
[2025-09-22 16:40:43,135] WARNING django.request:253 — Bad Request: /cart/api/add/
[2025-09-22 16:40:43,136] WARNING django.server:213 — "POST /cart/api/add/ HTTP/1.1" 400 5812
[2025-09-22 16:42:20,237] INFO django.utils.autoreload:265 — /app/cart/views.py changed, reloading.
[2025-09-22 16:42:21,101] INFO django.utils.autoreload:667 — Watching for file changes with StatReloader
[2025-09-23 12:41:16,867] INFO django.utils.autoreload:667 — Watching for file changes with StatReloader
[2025-09-23 12:41:19,485] ERROR django.request:253 — Internal Server Error: /
[2025-09-23 12:41:19,486] ERROR django.server:213 — "GET / HTTP/1.1" 500 5500
[2025-09-23 12:41:19,568] INFO django.server:213 — "GET /static/rest_framework/css/default.css HTTP/1.1" 304 0
[2025-09-23 12:41:19,568] INFO django.server:213 — "GET /static/rest_framework/css/bootstrap.min.css HTTP/1.1" 304 0
[2025-09-23 12:41:19,569] INFO django.server:213 — "GET /static/rest_framework/css/bootstrap-tweaks.css HTTP/1.1" 304 0
[2025-09-23 12:41:19,569] INFO django.server:213 — "GET /static/rest_framework/css/prettify.css HTTP/1.1" 304 0
[2025-09-23 12:41:19,573] INFO django.server:213 — "GET /static/rest_framework/js/csrf.js HTTP/1.1" 304 0
[2025-09-23 12:41:19,575] INFO django.server:213 — "GET /static/rest_framework/js/bootstrap.min.js HTTP/1.1" 304 0
[2025-09-23 12:41:19,576] INFO django.server:213 — "GET /static/rest_framework/js/jquery-3.7.1.min.js HTTP/1.1" 304 0
[2025-09-23 12:41:19,577] INFO django.server:213 — "GET /static/rest_framework/js/prettify-min.js HTTP/1.1" 304 0
[2025-09-23 12:41:19,577] INFO django.server:213 — "GET /static/rest_framework/js/ajax-form.js HTTP/1.1" 304 0
[2025-09-23 12:41:19,578] INFO django.server:213 — "GET /static/rest_framework/js/default.js HTTP/1.1" 304 0
[2025-09-23 12:41:19,579] INFO django.server:213 — "GET /static/rest_framework/js/load-ajax-form.js HTTP/1.1" 304 0
[2025-09-23 12:41:19,748] INFO django.server:213 — "GET /static/rest_framework/img/grid.png HTTP/1.1" 200 1458
[2025-09-23 12:41:19,951] WARNING django.request:253 — Not Found: /favicon.ico
[2025-09-23 12:41:19,952] WARNING django.server:213 — "GET /favicon.ico HTTP/1.1" 404 3299
[2025-09-23 12:41:25,787] INFO django.server:213 — "GET /products/api HTTP/1.1" 301 0
[2025-09-23 12:41:25,794] INFO django.server:213 — "GET /user/api/check-auth/ HTTP/1.1" 200 39
[2025-09-23 12:41:25,839] ERROR django.request:253 — Internal Server Error: /products/api/
[2025-09-23 12:41:25,839] ERROR django.server:213 — "GET /products/api/ HTTP/1.1" 500 317
[2025-09-23 12:43:45,080] INFO django.server:213 — "GET / HTTP/1.1" 200 6253
[2025-09-23 12:43:45,318] WARNING django.request:253 — Not Found: /favicon.ico
[2025-09-23 12:43:45,319] WARNING django.server:213 — "GET /favicon.ico HTTP/1.1" 404 3299
[2025-09-23 12:43:47,138] INFO django.server:213 — "GET /products/api HTTP/1.1" 301 0
[2025-09-23 12:43:47,153] INFO django.server:213 — "GET /user/api/check-auth/ HTTP/1.1" 200 39
[2025-09-23 12:43:47,178] INFO django.server:213 — "GET /products/api/ HTTP/1.1" 200 498
[2025-09-23 12:43:47,203] INFO django.server:213 — "GET /media/catalog/photo_2025-06-17_19-04-21.jpg HTTP/1.1" 304 0
[2025-09-23 12:43:58,693] INFO django.server:213 — "GET /products/1/ HTTP/1.1" 200 333
[2025-09-23 12:43:59,198] INFO django.server:213 — "GET /products/api HTTP/1.1" 301 0
[2025-09-23 12:43:59,218] INFO django.server:213 — "GET /products/api/ HTTP/1.1" 200 498
[2025-09-23 12:44:04,850] INFO django.server:213 — "GET /products/1/ HTTP/1.1" 200 333
[2025-09-23 12:44:05,943] INFO django.server:213 — "GET /products/api HTTP/1.1" 301 0
[2025-09-23 12:44:05,972] INFO django.server:213 — "GET /products/api/ HTTP/1.1" 200 498
[2025-09-23 12:44:31,003] INFO django.server:213 — "GET /products/1/ HTTP/1.1" 200 333
[2025-09-23 12:44:31,673] INFO django.server:213 — "GET /products/api HTTP/1.1" 301 0
[2025-09-23 12:44:31,693] INFO django.server:213 — "GET /products/api/ HTTP/1.1" 200 498
[2025-09-23 12:44:32,446] INFO django.server:213 — "GET /products/1/ HTTP/1.1" 200 333
[2025-09-23 12:44:32,806] INFO django.server:213 — "GET /products/api HTTP/1.1" 301 0
[2025-09-23 12:44:32,827] INFO django.server:213 — "GET /products/api/ HTTP/1.1" 200 498
[2025-09-23 12:44:42,269] INFO django.server:213 — "GET /products/1/ HTTP/1.1" 200 333
[2025-09-23 12:44:43,641] INFO django.server:213 — "GET /products/api HTTP/1.1" 301 0
[2025-09-23 12:44:43,663] INFO django.server:213 — "GET /products/api/ HTTP/1.1" 200 498
[2025-09-23 12:44:44,208] INFO django.server:213 — "GET /products/1/ HTTP/1.1" 200 333
[2025-09-23 12:44:49,362] INFO django.server:213 — "GET /products/api HTTP/1.1" 301 0
[2025-09-23 12:44:49,377] INFO django.server:213 — "GET /products/api/ HTTP/1.1" 200 498
[2025-09-23 12:44:50,649] INFO django.server:213 — "GET /products/1/ HTTP/1.1" 200 333
[2025-09-23 12:44:51,469] INFO django.server:213 — "OPTIONS /cart/api/add/ HTTP/1.1" 200 0
[2025-09-23 12:44:51,498] INFO django.server:213 — "POST /cart/api/add/ HTTP/1.1" 200 167
[2025-09-23 12:44:52,546] INFO django.server:213 — "GET /products/api HTTP/1.1" 301 0
[2025-09-23 12:44:52,569] INFO django.server:213 — "GET /products/api/ HTTP/1.1" 200 498
[2025-09-23 12:44:57,309] INFO django.server:213 — "GET /cart HTTP/1.1" 301 0
[2025-09-23 12:44:57,358] INFO django.server:213 — "GET /cart/ HTTP/1.1" 200 5262
[2025-09-23 12:45:03,052] WARNING django.request:253 — Not Found: /logout
[2025-09-23 12:45:03,053] WARNING django.server:213 — "GET /logout HTTP/1.1" 404 3284
[2025-09-23 12:45:09,118] INFO django.server:213 — "GET /user/logout HTTP/1.1" 301 0
[2025-09-23 12:45:09,154] INFO django.server:213 — "GET /user/logout/ HTTP/1.1" 200 5321
[2025-09-23 12:45:18,311] INFO django.server:213 — "GET /user/register HTTP/1.1" 301 0
[2025-09-23 12:45:18,359] INFO django.server:213 — "GET /user/register/ HTTP/1.1" 200 6962
[2025-09-23 12:46:08,308] INFO django.server:213 — "GET /user/register/ HTTP/1.1" 200 6962
[2025-09-23 12:47:09,695] INFO users.views:35 — user: john_doe
[2025-09-23 12:47:09,700] INFO django.server:213 — "POST /user/register/ HTTP/1.1" 201 7229
[2025-09-23 12:47:16,888] INFO django.server:213 — "GET /user/login HTTP/1.1" 301 0
[2025-09-23 12:47:16,922] INFO django.server:213 — "GET /user/login/ HTTP/1.1" 200 6919
[2025-09-23 12:47:24,339] ERROR django.request:253 — Internal Server Error: /user/login/
[2025-09-23 12:47:24,340] ERROR django.server:213 — "POST /user/login/ HTTP/1.1" 500 7066
[2025-09-23 12:47:41,709] ERROR django.request:253 — Internal Server Error: /user/login/
[2025-09-23 12:47:41,710] ERROR django.server:213 — "POST /user/login/ HTTP/1.1" 500 7066
[2025-09-23 12:47:52,131] ERROR django.request:253 — Internal Server Error: /user/login/
[2025-09-23 12:47:52,132] ERROR django.server:213 — "POST /user/login/ HTTP/1.1" 500 7056
[2025-09-23 12:48:06,052] INFO users.views:77 — user: john_doe
[2025-09-23 12:48:06,058] INFO django.server:213 — "POST /user/login/ HTTP/1.1" 200 7255
[2025-09-23 12:48:19,042] INFO django.server:213 — "GET / HTTP/1.1" 200 6263
[2025-09-23 12:48:25,060] INFO django.server:213 — "GET /cart HTTP/1.1" 301 0
[2025-09-23 12:48:25,103] INFO django.server:213 — "GET /cart/ HTTP/1.1" 200 5272
[2025-09-23 12:48:32,392] INFO django.server:213 — "GET /cart/api/add HTTP/1.1" 301 0
[2025-09-23 12:48:32,437] INFO django.server:213 — "GET /cart/api/add/ HTTP/1.1" 200 7106
[2025-09-23 12:48:35,628] WARNING django.request:253 — Not Found: /cart/api/add/1
[2025-09-23 12:48:35,629] WARNING django.server:213 — "GET /cart/api/add/1 HTTP/1.1" 404 4717
[2025-09-23 12:49:04,985] WARNING django.request:253 — Not Found: /cart/api/add/1
[2025-09-23 12:49:04,986] WARNING django.server:213 — "GET /cart/api/add/1 HTTP/1.1" 404 4717
[2025-09-23 12:49:08,288] WARNING django.request:253 — Not Found: /cart/api/add/1
[2025-09-23 12:49:08,289] WARNING django.server:213 — "GET /cart/api/add/1 HTTP/1.1" 404 4717
[2025-09-23 12:49:10,168] INFO django.server:213 — "GET /cart/api/add HTTP/1.1" 301 0
[2025-09-23 12:49:10,206] INFO django.server:213 — "GET /cart/api/add/ HTTP/1.1" 200 7106
[2025-09-23 12:49:35,595] INFO django.server:213 — "POST /cart/api/add/ HTTP/1.1" 200 7358
[2025-09-23 12:49:56,330] INFO django.server:213 — "GET /cart/ HTTP/1.1" 200 5523
[2025-09-23 12:50:05,940] INFO django.server:213 — "GET /cart/ HTTP/1.1" 200 55
[2025-09-23 12:50:32,370] INFO django.server:213 — "GET /products/api HTTP/1.1" 301 0
[2025-09-23 12:50:32,381] INFO django.server:213 — "GET /user/api/check-auth/ HTTP/1.1" 200 44
[2025-09-23 12:50:32,398] INFO django.server:213 — "GET /products/api/ HTTP/1.1" 200 498
[2025-09-23 12:50:38,206] INFO django.server:213 — "GET /cart/ HTTP/1.1" 200 55
[2025-09-23 12:50:44,345] INFO django.server:213 — "GET /products/api HTTP/1.1" 301 0
[2025-09-23 12:50:44,358] INFO django.server:213 — "GET /user/api/check-auth/ HTTP/1.1" 200 44
[2025-09-23 12:50:44,379] INFO django.server:213 — "GET /products/api/ HTTP/1.1" 200 498
[2025-09-23 12:50:46,304] INFO django.server:213 — "GET /cart/ HTTP/1.1" 200 55
[2025-09-23 12:54:17,357] INFO django.server:213 — "GET /products/api HTTP/1.1" 301 0
[2025-09-23 12:54:17,380] INFO django.server:213 — "GET /user/api/check-auth/ HTTP/1.1" 200 44
[2025-09-23 12:54:17,424] INFO django.server:213 — "GET /products/api/ HTTP/1.1" 200 498
[2025-09-23 12:54:18,879] INFO django.server:213 — "GET /cart/ HTTP/1.1" 200 55
[2025-09-23 12:54:34,914] INFO django.server:213 — "GET /products/api HTTP/1.1" 301 0
[2025-09-23 12:54:34,942] INFO django.server:213 — "GET /user/api/check-auth/ HTTP/1.1" 200 44
[2025-09-23 12:54:35,410] INFO django.server:213 — "GET /products/api/ HTTP/1.1" 200 498
[2025-09-23 12:54:36,557] INFO django.server:213 — "GET /cart/ HTTP/1.1" 200 55
[2025-09-23 12:55:02,213] INFO django.server:213 — "GET /products/api HTTP/1.1" 301 0
[2025-09-23 12:55:02,228] INFO django.server:213 — "GET /user/api/check-auth/ HTTP/1.1" 200 44
[2025-09-23 12:55:02,313] INFO django.server:213 — "GET /products/api/ HTTP/1.1" 200 498
[2025-09-23 12:55:02,405] INFO django.server:213 — "GET /media/catalog/photo_2025-06-17_19-04-21.jpg HTTP/1.1" 200 51047
[2025-09-23 12:55:03,852] INFO django.server:213 — "GET /cart/ HTTP/1.1" 200 55
[2025-09-23 12:55:13,028] INFO django.server:213 — "GET /products/api HTTP/1.1" 301 0
[2025-09-23 12:55:13,036] INFO django.server:213 — "GET /user/api/check-auth/ HTTP/1.1" 200 44
[2025-09-23 12:55:13,087] INFO django.server:213 — "GET /products/api/ HTTP/1.1" 200 498
[2025-09-23 12:55:16,158] INFO django.server:213 — "GET /cart/ HTTP/1.1" 200 55
[2025-09-23 12:56:17,692] INFO django.server:213 — "GET /products/api HTTP/1.1" 301 0
[2025-09-23 12:56:17,711] INFO django.server:213 — "GET /user/api/check-auth/ HTTP/1.1" 200 44
[2025-09-23 12:56:17,741] INFO django.server:213 — "GET /products/api/ HTTP/1.1" 200 498
[2025-09-23 12:56:21,994] INFO django.server:213 — "GET /products/api HTTP/1.1" 301 0
[2025-09-23 12:56:22,004] INFO django.server:213 — "GET /user/api/check-auth/ HTTP/1.1" 200 44
[2025-09-23 12:56:22,171] INFO django.server:213 — "GET /products/api/ HTTP/1.1" 200 498
[2025-09-23 12:56:22,972] INFO django.server:213 — "GET /cart/ HTTP/1.1" 200 55
[2025-09-23 12:56:32,985] INFO django.server:213 — "GET /cart/ HTTP/1.1" 200 5523
[2025-09-23 12:56:33,346] INFO django.server:213 — "GET /cart/ HTTP/1.1" 200 5523
[2025-09-23 12:56:42,409] INFO django.server:213 — "GET /products/api HTTP/1.1" 301 0
[2025-09-23 12:56:42,416] INFO django.server:213 — "GET /user/api/check-auth/ HTTP/1.1" 200 44
[2025-09-23 12:56:42,454] INFO django.server:213 — "GET /products/api/ HTTP/1.1" 200 498
[2025-09-23 12:56:44,856] INFO django.server:213 — "GET /cart/ HTTP/1.1" 200 55
[2025-09-23 12:59:14,762] INFO django.server:213 — "GET /cart/ HTTP/1.1" 200 5523
[2025-09-23 12:59:17,084] INFO django.server:213 — "GET /products/api HTTP/1.1" 301 0
[2025-09-23 12:59:17,090] INFO django.server:213 — "GET /user/api/check-auth/ HTTP/1.1" 200 44
[2025-09-23 12:59:17,110] INFO django.server:213 — "GET /products/api/ HTTP/1.1" 200 498
[2025-09-23 12:59:18,105] INFO django.server:213 — "GET /cart/ HTTP/1.1" 200 55
[2025-09-23 12:59:19,462] INFO django.server:213 — "GET /products/api HTTP/1.1" 301 0
[2025-09-23 12:59:19,471] INFO django.server:213 — "GET /user/api/check-auth/ HTTP/1.1" 200 44
[2025-09-23 12:59:19,501] INFO django.server:213 — "GET /products/api/ HTTP/1.1" 200 498
[2025-09-23 12:59:24,986] INFO django.server:213 — "GET /products/api HTTP/1.1" 301 0
[2025-09-23 12:59:24,994] INFO django.server:213 — "GET /user/api/check-auth/ HTTP/1.1" 200 44
[2025-09-23 12:59:25,051] INFO django.server:213 — "GET /products/api/ HTTP/1.1" 200 498
[2025-09-23 12:59:27,368] INFO django.server:213 — "GET /cart/ HTTP/1.1" 200 55
[2025-09-23 13:00:30,609] INFO django.utils.autoreload:265 — /app/cart/views.py changed, reloading.
[2025-09-23 13:00:31,607] INFO django.utils.autoreload:667 — Watching for file changes with StatReloader
[2025-09-23 13:00:32,172] INFO cart.views:24 — [{'id': 2, 'quantity': 1, 'product_title': 'tadwa', 'product_photo_url': '/media/catalog/photo_2025-06-17_19-04-21.jpg'}]
[2025-09-23 13:00:32,201] INFO django.server:213 — "GET /cart/ HTTP/1.1" 200 5523
[2025-09-23 13:02:17,414] INFO django.utils.autoreload:265 — /app/cart/views.py changed, reloading.
[2025-09-23 13:02:18,312] INFO django.utils.autoreload:667 — Watching for file changes with StatReloader
[2025-09-23 13:02:44,824] INFO django.server:213 — "GET /products/api HTTP/1.1" 301 0
[2025-09-23 13:02:44,832] INFO django.server:213 — "GET /user/api/check-auth/ HTTP/1.1" 200 44
[2025-09-23 13:02:44,875] INFO django.server:213 — "GET /products/api/ HTTP/1.1" 200 498
[2025-09-23 13:02:48,799] INFO cart.views:24 — []
[2025-09-23 13:02:48,802] INFO django.server:213 — "GET /cart/ HTTP/1.1" 200 58
[2025-09-23 13:02:59,564] INFO django.server:213 — "GET /products/api HTTP/1.1" 301 0
[2025-09-23 13:02:59,571] INFO django.server:213 — "GET /user/api/check-auth/ HTTP/1.1" 200 44
[2025-09-23 13:02:59,637] INFO django.server:213 — "GET /products/api/ HTTP/1.1" 200 498
[2025-09-23 13:03:08,175] INFO cart.views:24 — []
[2025-09-23 13:03:08,177] INFO django.server:213 — "GET /cart/ HTTP/1.1" 200 58
[2025-09-23 13:03:22,889] INFO django.server:213 — "GET /products/api HTTP/1.1" 301 0
[2025-09-23 13:03:22,896] INFO django.server:213 — "GET /user/api/check-auth/ HTTP/1.1" 200 44
[2025-09-23 13:03:22,925] INFO django.server:213 — "GET /products/api/ HTTP/1.1" 200 498
[2025-09-23 13:03:26,624] INFO django.server:213 — "GET /products/api HTTP/1.1" 301 0
[2025-09-23 13:03:26,632] INFO django.server:213 — "GET /user/api/check-auth/ HTTP/1.1" 200 44
[2025-09-23 13:03:26,734] INFO django.server:213 — "GET /products/api/ HTTP/1.1" 200 498
[2025-09-23 13:03:29,439] INFO cart.views:24 — []
[2025-09-23 13:03:29,443] INFO django.server:213 — "GET /cart/ HTTP/1.1" 200 58
[2025-09-23 13:04:39,329] INFO django.server:213 — "GET /user/api/check-auth/ HTTP/1.1" 200 44
[2025-09-23 13:04:43,429] INFO django.server:213 — "GET /products/api HTTP/1.1" 301 0
[2025-09-23 13:04:43,436] INFO django.server:213 — "GET /user/api/check-auth/ HTTP/1.1" 200 44
[2025-09-23 13:04:43,469] INFO django.server:213 — "GET /products/api/ HTTP/1.1" 200 498
[2025-09-23 13:04:47,110] INFO django.server:213 — "GET /user/api/check-auth/ HTTP/1.1" 200 44
[2025-09-23 13:04:49,525] INFO django.server:213 — "GET /products/api HTTP/1.1" 301 0
[2025-09-23 13:04:49,532] INFO django.server:213 — "GET /user/api/check-auth/ HTTP/1.1" 200 44
[2025-09-23 13:04:49,561] INFO django.server:213 — "GET /products/api/ HTTP/1.1" 200 498
[2025-09-23 13:05:01,912] INFO django.server:213 — "GET /products/1/ HTTP/1.1" 200 333
[2025-09-23 13:05:03,052] INFO django.server:213 — "GET /products/api HTTP/1.1" 301 0
[2025-09-23 13:05:03,074] INFO django.server:213 — "GET /products/api/ HTTP/1.1" 200 498
[2025-09-23 13:05:04,013] INFO django.server:213 — "GET /products/1/ HTTP/1.1" 200 333
[2025-09-23 13:05:04,578] INFO django.server:213 — "POST /cart/api/add/ HTTP/1.1" 200 167
[2025-09-23 13:05:05,154] INFO django.server:213 — "GET /products/api HTTP/1.1" 301 0
[2025-09-23 13:05:05,180] INFO django.server:213 — "GET /products/api/ HTTP/1.1" 200 498
[2025-09-23 13:05:05,871] INFO cart.views:24 — []
[2025-09-23 13:05:05,879] INFO django.server:213 — "GET /cart/ HTTP/1.1" 200 58
[2025-09-23 13:07:52,635] INFO django.server:213 — "GET /products/api HTTP/1.1" 301 0
[2025-09-23 13:07:52,649] INFO django.server:213 — "GET /user/api/check-auth/ HTTP/1.1" 200 44
[2025-09-23 13:07:52,672] INFO django.server:213 — "GET /products/api/ HTTP/1.1" 200 498
[2025-09-23 13:08:05,983] INFO django.utils.autoreload:667 — Watching for file changes with StatReloader
[2025-09-23 13:08:08,454] INFO django.server:213 — "GET /products/api HTTP/1.1" 301 0
[2025-09-23 13:08:08,462] INFO django.server:213 — "GET /user/api/check-auth/ HTTP/1.1" 200 44
[2025-09-23 13:08:08,575] INFO django.server:213 — "GET /products/api/ HTTP/1.1" 200 498
[2025-09-23 13:08:09,812] INFO django.server:213 — "GET /products/api HTTP/1.1" 301 0
[2025-09-23 13:08:09,818] INFO django.server:213 — "GET /user/api/check-auth/ HTTP/1.1" 200 44
[2025-09-23 13:08:09,896] INFO django.server:213 — "GET /products/api/ HTTP/1.1" 200 498
[2025-09-23 13:08:10,771] INFO cart.views:24 — []
[2025-09-23 13:08:10,776] INFO django.server:213 — "GET /cart/ HTTP/1.1" 200 58
[2025-09-23 13:09:57,604] INFO django.server:213 — "GET /products/api HTTP/1.1" 301 0
[2025-09-23 13:09:57,620] INFO django.server:213 — "GET /user/api/check-auth/ HTTP/1.1" 200 44
[2025-09-23 13:09:58,010] INFO django.server:213 — "GET /products/api/ HTTP/1.1" 200 498
[2025-09-23 13:10:03,009] INFO django.server:213 — "GET /user/logout HTTP/1.1" 301 0
[2025-09-23 13:10:03,095] INFO django.server:213 — "GET /user/logout/ HTTP/1.1" 200 5321
[2025-09-23 13:10:05,957] INFO django.server:213 — "GET /products/api HTTP/1.1" 301 0
[2025-09-23 13:10:05,957] INFO django.server:213 — "GET /user/api/check-auth/ HTTP/1.1" 200 23
[2025-09-23 13:10:06,006] INFO django.server:213 — "GET /products/api/ HTTP/1.1" 200 498
[2025-09-23 13:10:20,598] INFO django.server:213 — "GET /user/login HTTP/1.1" 301 0
[2025-09-23 13:10:20,660] INFO django.server:213 — "GET /user/login/ HTTP/1.1" 200 6919
[2025-09-23 13:11:06,928] INFO django.server:213 — "OPTIONS /user/login/ HTTP/1.1" 200 0
[2025-09-23 13:11:07,259] INFO users.views:77 — user: john_doe
[2025-09-23 13:11:07,314] INFO django.server:213 — "POST /user/login/ HTTP/1.1" 200 153
[2025-09-23 13:11:09,406] WARNING django.request:253 — Forbidden: /user/login/
[2025-09-23 13:11:09,407] WARNING django.server:213 — "POST /user/login/ HTTP/1.1" 403 108
[2025-09-23 13:14:33,483] INFO django.utils.autoreload:265 — /app/backend/settings.py changed, reloading.
[2025-09-23 13:14:34,672] INFO django.utils.autoreload:667 — Watching for file changes with StatReloader
[2025-09-23 13:14:58,007] INFO django.utils.autoreload:265 — /app/backend/settings.py changed, reloading.
[2025-09-23 13:14:58,896] INFO django.utils.autoreload:667 — Watching for file changes with StatReloader
[2025-09-23 13:15:08,315] INFO django.utils.autoreload:667 — Watching for file changes with StatReloader
[2025-09-23 13:15:11,225] INFO django.server:213 — "GET /products/api HTTP/1.1" 301 0
[2025-09-23 13:15:11,237] INFO django.server:213 — "GET /user/api/check-auth/ HTTP/1.1" 200 44
[2025-09-23 13:15:12,036] INFO django.server:213 — "GET /products/api HTTP/1.1" 301 0
[2025-09-23 13:15:12,043] INFO django.server:213 — "GET /user/api/check-auth/ HTTP/1.1" 200 44
[2025-09-23 13:15:12,087] INFO django.server:213 — "GET /products/api/ HTTP/1.1" 200 498
[2025-09-23 13:15:17,600] INFO django.server:213 — "GET /products/api HTTP/1.1" 301 0
[2025-09-23 13:15:17,608] INFO django.server:213 — "GET /user/api/check-auth/ HTTP/1.1" 200 44
[2025-09-23 13:15:17,637] INFO django.server:213 — "GET /products/api/ HTTP/1.1" 200 498
[2025-09-23 13:15:21,511] WARNING django.request:253 — Not Found: /logout
[2025-09-23 13:15:21,514] WARNING django.server:213 — "GET /logout HTTP/1.1" 404 3284
[2025-09-23 13:15:21,796] WARNING django.request:253 — Not Found: /favicon.ico
[2025-09-23 13:15:21,799] WARNING django.server:213 — "GET /favicon.ico HTTP/1.1" 404 3299
[2025-09-23 13:15:26,032] INFO django.server:213 — "GET /user/logout HTTP/1.1" 301 0
[2025-09-23 13:15:26,132] INFO django.server:213 — "GET /user/logout/ HTTP/1.1" 200 5321
[2025-09-23 13:15:30,613] WARNING django.request:253 — Not Found: /user/
[2025-09-23 13:15:30,614] WARNING django.server:213 — "GET /user/ HTTP/1.1" 404 4122
[2025-09-23 13:15:33,784] INFO django.server:213 — "GET /user/api/check-auth/ HTTP/1.1" 200 23
[2025-09-23 13:15:33,784] INFO django.server:213 — "GET /products/api HTTP/1.1" 301 0
[2025-09-23 13:15:33,813] INFO django.server:213 — "GET /products/api/ HTTP/1.1" 200 498
[2025-09-23 13:16:25,140] INFO users.views:77 — user: john_doe
[2025-09-23 13:16:25,144] INFO django.server:213 — "POST /user/login/ HTTP/1.1" 200 153
[2025-09-23 13:16:45,477] INFO django.server:213 — "GET /products/api HTTP/1.1" 301 0
[2025-09-23 13:16:45,547] INFO django.server:213 — "GET /user/api/check-auth/ HTTP/1.1" 200 44
[2025-09-23 13:16:45,618] INFO django.server:213 — "GET /products/api/ HTTP/1.1" 200 498
[2025-09-23 13:16:47,135] INFO cart.views:24 — []
[2025-09-23 13:16:47,139] INFO django.server:213 — "GET /cart/ HTTP/1.1" 200 58
[2025-09-23 13:17:20,420] INFO django.server:213 — "GET / HTTP/1.1" 200 6263
[2025-09-23 13:17:20,503] INFO django.server:213 — "GET /static/rest_framework/css/bootstrap.min.css HTTP/1.1" 200 121457
[2025-09-23 13:17:20,868] INFO django.server:213 — "GET /static/rest_framework/img/grid.png HTTP/1.1" 200 1458
[2025-09-23 13:17:22,213] INFO django.server:213 — "GET /products/api HTTP/1.1" 301 0
[2025-09-23 13:17:22,225] INFO django.server:213 — "GET /user/api/check-auth/ HTTP/1.1" 200 44
[2025-09-23 13:17:22,235] INFO django.server:213 — "GET /products/api/ HTTP/1.1" 200 498
[2025-09-23 13:17:28,098] INFO django.server:213 — "GET /cart HTTP/1.1" 301 0
[2025-09-23 13:17:28,157] INFO cart.views:24 — [{'id': 2, 'quantity': 1, 'product_title': 'tadwa', 'product_photo_url': '/media/catalog/photo_2025-06-17_19-04-21.jpg'}]
[2025-09-23 13:17:28,160] INFO django.server:213 — "GET /cart/ HTTP/1.1" 200 5526
[2025-09-23 13:17:54,367] INFO cart.views:24 — []
[2025-09-23 13:17:54,372] INFO django.server:213 — "GET /cart/ HTTP/1.1" 200 58
[2025-09-23 13:19:55,858] INFO django.utils.autoreload:667 — Watching for file changes with StatReloader
[2025-09-23 13:19:57,711] INFO django.server:213 — "GET /products/api HTTP/1.1" 301 0
[2025-09-23 13:19:57,730] INFO django.server:213 — "GET /user/api/check-auth/ HTTP/1.1" 200 44
[2025-09-23 13:19:57,927] INFO django.server:213 — "GET /products/api/ HTTP/1.1" 200 498
[2025-09-23 13:19:59,172] INFO django.server:213 — "GET /products/api HTTP/1.1" 301 0
[2025-09-23 13:19:59,182] INFO django.server:213 — "GET /user/api/check-auth/ HTTP/1.1" 200 44
[2025-09-23 13:19:59,216] INFO django.server:213 — "GET /products/api/ HTTP/1.1" 200 498
[2025-09-23 13:20:05,180] INFO cart.views:24 — []
[2025-09-23 13:20:05,183] INFO django.server:213 — "GET /cart/ HTTP/1.1" 200 58
[2025-09-23 13:21:28,915] INFO django.server:213 — "GET /products/api HTTP/1.1" 301 0
[2025-09-23 13:21:28,932] INFO django.server:213 — "GET /user/api/check-auth/ HTTP/1.1" 200 44
[2025-09-23 13:21:28,997] INFO django.server:213 — "GET /products/api/ HTTP/1.1" 200 498
[2025-09-23 13:21:31,460] INFO cart.views:24 — []
[2025-09-23 13:21:31,464] INFO django.server:213 — "GET /cart/ HTTP/1.1" 200 58
[2025-09-23 13:24:29,922] INFO django.utils.autoreload:667 — Watching for file changes with StatReloader
[2025-09-23 13:24:53,277] INFO django.utils.autoreload:265 — /app/backend/settings.py changed, reloading.
[2025-09-23 13:24:54,044] INFO django.utils.autoreload:667 — Watching for file changes with StatReloader
[2025-09-23 13:24:59,249] INFO django.utils.autoreload:667 — Watching for file changes with StatReloader
[2025-09-23 13:25:00,282] INFO django.server:213 — "GET /products/api HTTP/1.1" 301 0
[2025-09-23 13:25:00,297] INFO django.server:213 — "GET /user/api/check-auth/ HTTP/1.1" 200 44
[2025-09-23 13:25:00,348] INFO django.server:213 — "GET /products/api/ HTTP/1.1" 200 498
[2025-09-23 13:25:02,004] INFO django.server:213 — "GET /products/api HTTP/1.1" 301 0
[2025-09-23 13:25:02,010] INFO django.server:213 — "GET /user/api/check-auth/ HTTP/1.1" 200 44
[2025-09-23 13:25:02,142] INFO django.server:213 — "GET /products/api/ HTTP/1.1" 200 498
[2025-09-23 13:25:03,871] INFO cart.views:24 — [{'id': 2, 'quantity': 1, 'product_title': 'tadwa', 'product_photo_url': '/media/catalog/photo_2025-06-17_19-04-21.jpg'}]
[2025-09-23 13:25:03,873] INFO django.server:213 — "GET /cart/ HTTP/1.1" 200 165
[2025-09-23 13:29:54,370] INFO django.utils.autoreload:265 — /app/users/views.py changed, reloading.
[2025-09-23 13:29:55,487] INFO django.utils.autoreload:667 — Watching for file changes with StatReloader
